package io.github.cappycot.kemonocraft.worldgen;

/*
*** MADE BY MRPONYCAPTAIN'S .SCHEMATIC TO .JAVA CONVERTING TOOL v2.0 ***
*/

import java.util.Random;

import cpw.mods.fml.common.IWorldGenerator;
import net.minecraft.block.Block;
import net.minecraft.init.Blocks;
import net.minecraft.world.World;
import net.minecraft.world.chunk.IChunkProvider;
import net.minecraft.world.gen.feature.WorldGenerator;

public class TestGenerator extends WorldGenerator implements IWorldGenerator {
	protected Block[] getValidSpawnBlocks() {
		return new Block[] { Blocks.air, Blocks.stone, Blocks.grass, Blocks.dirt, Blocks.cobblestone, Blocks.sand };
	}

	public boolean locationIsValidSpawn(World world, int i, int j, int k) {
		int distanceToAir = 0;
		Block check = world.getBlock(i, j, k);

		while (check != Blocks.air) {
			if (distanceToAir > 2) {
				return false;
			}

			distanceToAir++;
			check = world.getBlock(i, j + distanceToAir, k);
		}

		j += distanceToAir - 1;

		Block block = world.getBlock(i, j, k);
		Block blockAbove = world.getBlock(i, j + 1, k);
		Block blockBelow = world.getBlock(i, j - 1, k);

		for (Block x : getValidSpawnBlocks()) {
			if (blockAbove != Blocks.air) {
				return false;
			}
			if (block == x) {
				return true;
			} else if (block == Blocks.snow && blockBelow == x) {
				return true;
			}
		}

		return false;
	}

	public TestGenerator() {
	}

	@Override
	public void generate(Random random, int chunkX, int chunkZ, World world, IChunkProvider chunkGenerator,
			IChunkProvider chunkProvider) {
		this.generate(world, random, chunkX * 16 + random.nextInt(16), random.nextInt(64) + 16,
				chunkZ * 16 + random.nextInt(16));
	}

	public void setBlock(World world, int x, int y, int z, Block block, int metadata) {
		Block b1 = world.getBlock(x, y, z);

		if (b1.isAir(world, x, y, z) || b1.isLeaves(world, x, y, z)) {
			world.setBlock(x, y, z, block, metadata, 2);
		}
	}

	public boolean generate(World world, Random rand, int i, int j, int k) {
		// check that each corner is one of the valid spawn blocks
		if (!locationIsValidSpawn(world, i, j, k) || !locationIsValidSpawn(world, i + 16, j, k)
				|| !locationIsValidSpawn(world, i + 16, j, k + 26) || !locationIsValidSpawn(world, i, j, k + 26)) {
			return false;
		}

		k = k - 10;
		i = i - 10;

		this.setBlock(world, i + 0, j + 0, k + 19, Blocks.planks, 0);
		this.setBlock(world, i + 0, j + 0, k + 20, Blocks.planks, 0);
		this.setBlock(world, i + 0, j + 0, k + 21, Blocks.planks, 0);
		this.setBlock(world, i + 0, j + 0, k + 22, Blocks.planks, 0);
		this.setBlock(world, i + 0, j + 1, k + 22, Blocks.fence, 0);
		this.setBlock(world, i + 1, j + 0, k + 19, Blocks.planks, 0);
		this.setBlock(world, i + 1, j + 0, k + 20, Blocks.planks, 0);
		this.setBlock(world, i + 1, j + 0, k + 21, Blocks.planks, 0);
		this.setBlock(world, i + 1, j + 0, k + 22, Blocks.planks, 0);
		this.setBlock(world, i + 1, j + 0, k + 23, Blocks.planks, 0);
		this.setBlock(world, i + 1, j + 1, k + 22, Blocks.fence, 0);
		this.setBlock(world, i + 1, j + 1, k + 23, Blocks.fence, 0);
		this.setBlock(world, i + 2, j + 0, k + 19, Blocks.planks, 0);
		this.setBlock(world, i + 2, j + 0, k + 20, Blocks.planks, 0);
		this.setBlock(world, i + 2, j + 0, k + 21, Blocks.planks, 0);
		this.setBlock(world, i + 2, j + 0, k + 22, Blocks.planks, 0);
		this.setBlock(world, i + 2, j + 0, k + 23, Blocks.planks, 0);
		this.setBlock(world, i + 2, j + 0, k + 24, Blocks.planks, 0);
		this.setBlock(world, i + 2, j + 1, k + 23, Blocks.fence, 0);
		this.setBlock(world, i + 2, j + 1, k + 24, Blocks.fence, 0);
		this.setBlock(world, i + 2, j + 5, k + 1, Blocks.air, 3);
		this.setBlock(world, i + 2, j + 5, k + 2, Blocks.air, 3);
		this.setBlock(world, i + 2, j + 5, k + 3, Blocks.air, 3);
		this.setBlock(world, i + 2, j + 5, k + 4, Blocks.air, 3);
		this.setBlock(world, i + 2, j + 5, k + 5, Blocks.air, 3);
		this.setBlock(world, i + 2, j + 5, k + 6, Blocks.air, 3);
		this.setBlock(world, i + 2, j + 5, k + 7, Blocks.air, 3);
		this.setBlock(world, i + 2, j + 5, k + 8, Blocks.air, 3);
		this.setBlock(world, i + 2, j + 5, k + 9, Blocks.air, 3);
		this.setBlock(world, i + 2, j + 5, k + 10, Blocks.air, 3);
		this.setBlock(world, i + 2, j + 5, k + 11, Blocks.air, 3);
		this.setBlock(world, i + 2, j + 5, k + 12, Blocks.air, 3);
		this.setBlock(world, i + 2, j + 5, k + 13, Blocks.air, 3);
		this.setBlock(world, i + 2, j + 5, k + 14, Blocks.air, 3);
		this.setBlock(world, i + 2, j + 5, k + 15, Blocks.air, 3);
		this.setBlock(world, i + 2, j + 5, k + 16, Blocks.air, 3);
		this.setBlock(world, i + 2, j + 5, k + 17, Blocks.air, 3);
		this.setBlock(world, i + 2, j + 5, k + 18, Blocks.air, 3);
		this.setBlock(world, i + 2, j + 5, k + 19, Blocks.air, 3);
		this.setBlock(world, i + 2, j + 6, k + 2, Blocks.air, 11);
		this.setBlock(world, i + 2, j + 6, k + 3, Blocks.air, 11);
		this.setBlock(world, i + 2, j + 6, k + 4, Blocks.air, 11);
		this.setBlock(world, i + 2, j + 6, k + 5, Blocks.air, 11);
		this.setBlock(world, i + 2, j + 6, k + 6, Blocks.air, 11);
		this.setBlock(world, i + 2, j + 6, k + 7, Blocks.air, 11);
		this.setBlock(world, i + 2, j + 6, k + 8, Blocks.air, 11);
		this.setBlock(world, i + 2, j + 6, k + 9, Blocks.air, 11);
		this.setBlock(world, i + 2, j + 6, k + 10, Blocks.air, 11);
		this.setBlock(world, i + 2, j + 6, k + 11, Blocks.air, 11);
		this.setBlock(world, i + 2, j + 6, k + 12, Blocks.air, 11);
		this.setBlock(world, i + 2, j + 6, k + 13, Blocks.air, 11);
		this.setBlock(world, i + 2, j + 6, k + 14, Blocks.air, 11);
		this.setBlock(world, i + 2, j + 6, k + 15, Blocks.air, 11);
		this.setBlock(world, i + 2, j + 6, k + 16, Blocks.air, 11);
		this.setBlock(world, i + 2, j + 6, k + 17, Blocks.air, 11);
		this.setBlock(world, i + 2, j + 6, k + 18, Blocks.air, 11);
		this.setBlock(world, i + 3, j + 0, k + 2, Blocks.cobblestone, 0);
		this.setBlock(world, i + 3, j + 0, k + 3, Blocks.cobblestone, 0);
		this.setBlock(world, i + 3, j + 0, k + 4, Blocks.cobblestone, 0);
		this.setBlock(world, i + 3, j + 0, k + 5, Blocks.cobblestone, 0);
		this.setBlock(world, i + 3, j + 0, k + 6, Blocks.cobblestone, 0);
		this.setBlock(world, i + 3, j + 0, k + 7, Blocks.cobblestone, 0);
		this.setBlock(world, i + 3, j + 0, k + 8, Blocks.cobblestone, 0);
		this.setBlock(world, i + 3, j + 0, k + 9, Blocks.cobblestone, 0);
		this.setBlock(world, i + 3, j + 0, k + 10, Blocks.cobblestone, 0);
		this.setBlock(world, i + 3, j + 0, k + 11, Blocks.cobblestone, 0);
		this.setBlock(world, i + 3, j + 0, k + 12, Blocks.cobblestone, 0);
		this.setBlock(world, i + 3, j + 0, k + 13, Blocks.cobblestone, 0);
		this.setBlock(world, i + 3, j + 0, k + 14, Blocks.cobblestone, 0);
		this.setBlock(world, i + 3, j + 0, k + 15, Blocks.cobblestone, 0);
		this.setBlock(world, i + 3, j + 0, k + 16, Blocks.cobblestone, 0);
		this.setBlock(world, i + 3, j + 0, k + 17, Blocks.cobblestone, 0);
		this.setBlock(world, i + 3, j + 0, k + 18, Blocks.cobblestone, 0);
		this.setBlock(world, i + 3, j + 0, k + 19, Blocks.planks, 0);
		this.setBlock(world, i + 3, j + 0, k + 20, Blocks.planks, 0);
		this.setBlock(world, i + 3, j + 0, k + 21, Blocks.planks, 0);
		this.setBlock(world, i + 3, j + 0, k + 22, Blocks.planks, 0);
		this.setBlock(world, i + 3, j + 0, k + 23, Blocks.planks, 0);
		this.setBlock(world, i + 3, j + 0, k + 24, Blocks.planks, 0);
		this.setBlock(world, i + 3, j + 1, k + 2, Blocks.sandstone, 0);
		this.setBlock(world, i + 3, j + 1, k + 3, Blocks.sandstone, 0);
		this.setBlock(world, i + 3, j + 1, k + 4, Blocks.sandstone, 0);
		this.setBlock(world, i + 3, j + 1, k + 5, Blocks.sandstone, 0);
		this.setBlock(world, i + 3, j + 1, k + 6, Blocks.sandstone, 0);
		this.setBlock(world, i + 3, j + 1, k + 7, Blocks.sandstone, 0);
		this.setBlock(world, i + 3, j + 1, k + 8, Blocks.sandstone, 0);
		this.setBlock(world, i + 3, j + 1, k + 9, Blocks.sandstone, 0);
		this.setBlock(world, i + 3, j + 1, k + 10, Blocks.sandstone, 0);
		this.setBlock(world, i + 3, j + 1, k + 11, Blocks.sandstone, 0);
		this.setBlock(world, i + 3, j + 1, k + 12, Blocks.sandstone, 0);
		this.setBlock(world, i + 3, j + 1, k + 13, Blocks.sandstone, 0);
		this.setBlock(world, i + 3, j + 1, k + 14, Blocks.sandstone, 0);
		this.setBlock(world, i + 3, j + 1, k + 15, Blocks.sandstone, 0);
		this.setBlock(world, i + 3, j + 1, k + 16, Blocks.sandstone, 0);
		this.setBlock(world, i + 3, j + 1, k + 17, Blocks.sandstone, 0);
		this.setBlock(world, i + 3, j + 1, k + 18, Blocks.sandstone, 0);
		this.setBlock(world, i + 3, j + 1, k + 21, Blocks.spruce_stairs, 1);
		this.setBlock(world, i + 3, j + 1, k + 24, Blocks.fence, 0);
		this.setBlock(world, i + 3, j + 2, k + 2, Blocks.sandstone, 0);
		this.setBlock(world, i + 3, j + 2, k + 3, Blocks.sandstone, 0);
		this.setBlock(world, i + 3, j + 2, k + 4, Blocks.sandstone, 0);
		this.setBlock(world, i + 3, j + 2, k + 5, Blocks.sandstone, 0);
		this.setBlock(world, i + 3, j + 2, k + 6, Blocks.sandstone, 0);
		this.setBlock(world, i + 3, j + 2, k + 7, Blocks.sandstone, 0);
		this.setBlock(world, i + 3, j + 2, k + 8, Blocks.sandstone, 0);
		this.setBlock(world, i + 3, j + 2, k + 9, Blocks.sandstone, 0);
		this.setBlock(world, i + 3, j + 2, k + 10, Blocks.sandstone, 0);
		this.setBlock(world, i + 3, j + 2, k + 11, Blocks.sandstone, 0);
		this.setBlock(world, i + 3, j + 2, k + 12, Blocks.sandstone, 0);
		this.setBlock(world, i + 3, j + 2, k + 13, Blocks.sandstone, 0);
		this.setBlock(world, i + 3, j + 2, k + 14, Blocks.sandstone, 0);
		this.setBlock(world, i + 3, j + 2, k + 15, Blocks.sandstone, 0);
		this.setBlock(world, i + 3, j + 2, k + 16, Blocks.sandstone, 0);
		this.setBlock(world, i + 3, j + 2, k + 17, Blocks.sandstone, 0);
		this.setBlock(world, i + 3, j + 2, k + 18, Blocks.sandstone, 0);
		this.setBlock(world, i + 3, j + 3, k + 2, Blocks.sandstone, 0);
		this.setBlock(world, i + 3, j + 3, k + 3, Blocks.sandstone, 0);
		this.setBlock(world, i + 3, j + 3, k + 4, Blocks.sandstone, 0);
		this.setBlock(world, i + 3, j + 3, k + 5, Blocks.sandstone, 0);
		this.setBlock(world, i + 3, j + 3, k + 6, Blocks.sandstone, 0);
		this.setBlock(world, i + 3, j + 3, k + 7, Blocks.sandstone, 0);
		this.setBlock(world, i + 3, j + 3, k + 8, Blocks.sandstone, 0);
		this.setBlock(world, i + 3, j + 3, k + 9, Blocks.sandstone, 0);
		this.setBlock(world, i + 3, j + 3, k + 10, Blocks.sandstone, 0);
		this.setBlock(world, i + 3, j + 3, k + 11, Blocks.sandstone, 0);
		this.setBlock(world, i + 3, j + 3, k + 12, Blocks.sandstone, 0);
		this.setBlock(world, i + 3, j + 3, k + 13, Blocks.sandstone, 0);
		this.setBlock(world, i + 3, j + 3, k + 14, Blocks.sandstone, 0);
		this.setBlock(world, i + 3, j + 3, k + 15, Blocks.sandstone, 0);
		this.setBlock(world, i + 3, j + 3, k + 16, Blocks.sandstone, 0);
		this.setBlock(world, i + 3, j + 3, k + 17, Blocks.sandstone, 0);
		this.setBlock(world, i + 3, j + 3, k + 18, Blocks.sandstone, 0);
		this.setBlock(world, i + 3, j + 4, k + 2, Blocks.sandstone, 0);
		this.setBlock(world, i + 3, j + 4, k + 3, Blocks.sandstone, 0);
		this.setBlock(world, i + 3, j + 4, k + 4, Blocks.sandstone, 0);
		this.setBlock(world, i + 3, j + 4, k + 5, Blocks.sandstone, 0);
		this.setBlock(world, i + 3, j + 4, k + 6, Blocks.sandstone, 0);
		this.setBlock(world, i + 3, j + 4, k + 7, Blocks.sandstone, 0);
		this.setBlock(world, i + 3, j + 4, k + 8, Blocks.sandstone, 0);
		this.setBlock(world, i + 3, j + 4, k + 9, Blocks.sandstone, 0);
		this.setBlock(world, i + 3, j + 4, k + 10, Blocks.sandstone, 0);
		this.setBlock(world, i + 3, j + 4, k + 11, Blocks.sandstone, 0);
		this.setBlock(world, i + 3, j + 4, k + 12, Blocks.sandstone, 0);
		this.setBlock(world, i + 3, j + 4, k + 13, Blocks.sandstone, 0);
		this.setBlock(world, i + 3, j + 4, k + 14, Blocks.sandstone, 0);
		this.setBlock(world, i + 3, j + 4, k + 15, Blocks.sandstone, 0);
		this.setBlock(world, i + 3, j + 4, k + 16, Blocks.sandstone, 0);
		this.setBlock(world, i + 3, j + 4, k + 17, Blocks.sandstone, 0);
		this.setBlock(world, i + 3, j + 4, k + 18, Blocks.sandstone, 0);
		this.setBlock(world, i + 3, j + 5, k + 2, Blocks.sandstone, 0);
		this.setBlock(world, i + 3, j + 5, k + 3, Blocks.sandstone, 0);
		this.setBlock(world, i + 3, j + 5, k + 4, Blocks.sandstone, 0);
		this.setBlock(world, i + 3, j + 5, k + 5, Blocks.sandstone, 0);
		this.setBlock(world, i + 3, j + 5, k + 6, Blocks.sandstone, 0);
		this.setBlock(world, i + 3, j + 5, k + 7, Blocks.sandstone, 0);
		this.setBlock(world, i + 3, j + 5, k + 8, Blocks.sandstone, 0);
		this.setBlock(world, i + 3, j + 5, k + 9, Blocks.sandstone, 0);
		this.setBlock(world, i + 3, j + 5, k + 10, Blocks.sandstone, 0);
		this.setBlock(world, i + 3, j + 5, k + 11, Blocks.sandstone, 0);
		this.setBlock(world, i + 3, j + 5, k + 12, Blocks.sandstone, 0);
		this.setBlock(world, i + 3, j + 5, k + 13, Blocks.sandstone, 0);
		this.setBlock(world, i + 3, j + 5, k + 14, Blocks.sandstone, 0);
		this.setBlock(world, i + 3, j + 5, k + 15, Blocks.sandstone, 0);
		this.setBlock(world, i + 3, j + 5, k + 16, Blocks.sandstone, 0);
		this.setBlock(world, i + 3, j + 5, k + 17, Blocks.sandstone, 0);
		this.setBlock(world, i + 3, j + 5, k + 18, Blocks.sandstone, 0);
		this.setBlock(world, i + 3, j + 6, k + 1, Blocks.air, 3);
		this.setBlock(world, i + 3, j + 6, k + 2, Blocks.air, 3);
		this.setBlock(world, i + 3, j + 6, k + 3, Blocks.air, 3);
		this.setBlock(world, i + 3, j + 6, k + 4, Blocks.air, 3);
		this.setBlock(world, i + 3, j + 6, k + 5, Blocks.air, 3);
		this.setBlock(world, i + 3, j + 6, k + 6, Blocks.air, 3);
		this.setBlock(world, i + 3, j + 6, k + 7, Blocks.air, 3);
		this.setBlock(world, i + 3, j + 6, k + 8, Blocks.air, 3);
		this.setBlock(world, i + 3, j + 6, k + 9, Blocks.air, 3);
		this.setBlock(world, i + 3, j + 6, k + 10, Blocks.air, 3);
		this.setBlock(world, i + 3, j + 6, k + 11, Blocks.air, 3);
		this.setBlock(world, i + 3, j + 6, k + 12, Blocks.air, 3);
		this.setBlock(world, i + 3, j + 6, k + 13, Blocks.air, 3);
		this.setBlock(world, i + 3, j + 6, k + 14, Blocks.air, 3);
		this.setBlock(world, i + 3, j + 6, k + 15, Blocks.air, 3);
		this.setBlock(world, i + 3, j + 6, k + 16, Blocks.air, 3);
		this.setBlock(world, i + 3, j + 6, k + 17, Blocks.air, 3);
		this.setBlock(world, i + 3, j + 6, k + 18, Blocks.air, 3);
		this.setBlock(world, i + 3, j + 6, k + 19, Blocks.air, 3);
		this.setBlock(world, i + 3, j + 7, k + 1, Blocks.air, 3);
		this.setBlock(world, i + 3, j + 7, k + 2, Blocks.air, 3);
		this.setBlock(world, i + 3, j + 7, k + 3, Blocks.air, 3);
		this.setBlock(world, i + 3, j + 7, k + 4, Blocks.air, 3);
		this.setBlock(world, i + 3, j + 7, k + 5, Blocks.air, 3);
		this.setBlock(world, i + 3, j + 7, k + 6, Blocks.air, 3);
		this.setBlock(world, i + 3, j + 7, k + 7, Blocks.air, 3);
		this.setBlock(world, i + 3, j + 7, k + 8, Blocks.air, 3);
		this.setBlock(world, i + 3, j + 7, k + 9, Blocks.air, 3);
		this.setBlock(world, i + 3, j + 7, k + 10, Blocks.air, 3);
		this.setBlock(world, i + 3, j + 7, k + 11, Blocks.air, 3);
		this.setBlock(world, i + 3, j + 7, k + 12, Blocks.air, 3);
		this.setBlock(world, i + 3, j + 7, k + 13, Blocks.air, 3);
		this.setBlock(world, i + 3, j + 7, k + 14, Blocks.air, 3);
		this.setBlock(world, i + 3, j + 7, k + 15, Blocks.air, 3);
		this.setBlock(world, i + 3, j + 7, k + 16, Blocks.air, 3);
		this.setBlock(world, i + 3, j + 7, k + 17, Blocks.air, 3);
		this.setBlock(world, i + 3, j + 7, k + 18, Blocks.air, 3);
		this.setBlock(world, i + 3, j + 7, k + 19, Blocks.air, 3);
		this.setBlock(world, i + 3, j + 8, k + 2, Blocks.air, 11);
		this.setBlock(world, i + 3, j + 8, k + 3, Blocks.air, 11);
		this.setBlock(world, i + 3, j + 8, k + 4, Blocks.air, 11);
		this.setBlock(world, i + 3, j + 8, k + 5, Blocks.air, 11);
		this.setBlock(world, i + 3, j + 8, k + 6, Blocks.air, 11);
		this.setBlock(world, i + 3, j + 8, k + 7, Blocks.air, 11);
		this.setBlock(world, i + 3, j + 8, k + 8, Blocks.air, 11);
		this.setBlock(world, i + 3, j + 8, k + 9, Blocks.air, 11);
		this.setBlock(world, i + 3, j + 8, k + 10, Blocks.air, 11);
		this.setBlock(world, i + 3, j + 8, k + 11, Blocks.air, 11);
		this.setBlock(world, i + 3, j + 8, k + 12, Blocks.air, 11);
		this.setBlock(world, i + 3, j + 8, k + 13, Blocks.air, 11);
		this.setBlock(world, i + 3, j + 8, k + 14, Blocks.air, 11);
		this.setBlock(world, i + 3, j + 8, k + 15, Blocks.air, 11);
		this.setBlock(world, i + 3, j + 8, k + 16, Blocks.air, 11);
		this.setBlock(world, i + 3, j + 8, k + 17, Blocks.air, 11);
		this.setBlock(world, i + 3, j + 8, k + 18, Blocks.air, 11);
		this.setBlock(world, i + 4, j + 0, k + 2, Blocks.cobblestone, 0);
		this.setBlock(world, i + 4, j + 0, k + 3, Blocks.cobblestone, 0);
		this.setBlock(world, i + 4, j + 0, k + 4, Blocks.cobblestone, 0);
		this.setBlock(world, i + 4, j + 0, k + 5, Blocks.cobblestone, 0);
		this.setBlock(world, i + 4, j + 0, k + 6, Blocks.cobblestone, 0);
		this.setBlock(world, i + 4, j + 0, k + 7, Blocks.cobblestone, 0);
		this.setBlock(world, i + 4, j + 0, k + 8, Blocks.cobblestone, 0);
		this.setBlock(world, i + 4, j + 0, k + 9, Blocks.cobblestone, 0);
		this.setBlock(world, i + 4, j + 0, k + 10, Blocks.cobblestone, 0);
		this.setBlock(world, i + 4, j + 0, k + 11, Blocks.cobblestone, 0);
		this.setBlock(world, i + 4, j + 0, k + 12, Blocks.cobblestone, 0);
		this.setBlock(world, i + 4, j + 0, k + 13, Blocks.cobblestone, 0);
		this.setBlock(world, i + 4, j + 0, k + 14, Blocks.cobblestone, 0);
		this.setBlock(world, i + 4, j + 0, k + 15, Blocks.cobblestone, 0);
		this.setBlock(world, i + 4, j + 0, k + 16, Blocks.cobblestone, 0);
		this.setBlock(world, i + 4, j + 0, k + 17, Blocks.cobblestone, 0);
		this.setBlock(world, i + 4, j + 0, k + 18, Blocks.cobblestone, 0);
		this.setBlock(world, i + 4, j + 0, k + 19, Blocks.planks, 0);
		this.setBlock(world, i + 4, j + 0, k + 20, Blocks.planks, 0);
		this.setBlock(world, i + 4, j + 0, k + 21, Blocks.planks, 0);
		this.setBlock(world, i + 4, j + 0, k + 22, Blocks.planks, 0);
		this.setBlock(world, i + 4, j + 0, k + 23, Blocks.planks, 0);
		this.setBlock(world, i + 4, j + 0, k + 24, Blocks.planks, 0);
		this.setBlock(world, i + 4, j + 0, k + 25, Blocks.planks, 0);
		this.setBlock(world, i + 4, j + 1, k + 2, Blocks.sandstone, 0);
		this.setBlock(world, i + 4, j + 1, k + 3, Blocks.planks, 1);
		this.setBlock(world, i + 4, j + 1, k + 4, Blocks.stone_slab, 3);
		this.setBlock(world, i + 4, j + 1, k + 5, Blocks.stone_slab, 3);
		this.setBlock(world, i + 4, j + 1, k + 6, Blocks.stone_slab, 3);
		this.setBlock(world, i + 4, j + 1, k + 7, Blocks.stone_slab, 3);
		this.setBlock(world, i + 4, j + 1, k + 8, Blocks.stone_slab, 3);
		this.setBlock(world, i + 4, j + 1, k + 9, Blocks.planks, 1);
		this.setBlock(world, i + 4, j + 1, k + 10, Blocks.stone_stairs, 3);
		this.setBlock(world, i + 4, j + 1, k + 11, Blocks.stone_slab, 3);
		this.setBlock(world, i + 4, j + 1, k + 12, Blocks.planks, 1);
		this.setBlock(world, i + 4, j + 1, k + 13, Blocks.planks, 1);
		this.setBlock(world, i + 4, j + 1, k + 14, Blocks.planks, 1);
		this.setBlock(world, i + 4, j + 1, k + 15, Blocks.planks, 1);
		this.setBlock(world, i + 4, j + 1, k + 16, Blocks.planks, 1);
		this.setBlock(world, i + 4, j + 1, k + 17, Blocks.sandstone, 0);
		this.setBlock(world, i + 4, j + 1, k + 18, Blocks.sandstone, 0);
		this.setBlock(world, i + 4, j + 1, k + 21, Blocks.spruce_stairs, 4);
		this.setBlock(world, i + 4, j + 1, k + 22, Blocks.spruce_stairs, 7);
		this.setBlock(world, i + 4, j + 1, k + 24, Blocks.fence, 0);
		this.setBlock(world, i + 4, j + 1, k + 25, Blocks.fence, 0);
		this.setBlock(world, i + 4, j + 2, k + 2, Blocks.planks, 1);
		this.setBlock(world, i + 4, j + 2, k + 3, Blocks.air, 5);
		this.setBlock(world, i + 4, j + 2, k + 8, Blocks.air, 6);
		this.setBlock(world, i + 4, j + 2, k + 9, Blocks.air, 3);
		this.setBlock(world, i + 4, j + 2, k + 12, Blocks.planks, 1);
		this.setBlock(world, i + 4, j + 2, k + 13, Blocks.cauldron, 3);
		this.setBlock(world, i + 4, j + 2, k + 14, Blocks.cauldron, 3);
		this.setBlock(world, i + 4, j + 2, k + 15, Blocks.cauldron, 3);
		this.setBlock(world, i + 4, j + 2, k + 16, Blocks.planks, 1);
		this.setBlock(world, i + 4, j + 2, k + 17, Blocks.sandstone, 0);
		this.setBlock(world, i + 4, j + 2, k + 18, Blocks.planks, 1);
		this.setBlock(world, i + 4, j + 3, k + 2, Blocks.planks, 1);
		this.setBlock(world, i + 4, j + 3, k + 3, Blocks.chest, 5);
		this.setBlock(world, i + 4, j + 3, k + 7, Blocks.air, 6);
		this.setBlock(world, i + 4, j + 3, k + 8, Blocks.air, 3);
		this.setBlock(world, i + 4, j + 3, k + 12, Blocks.planks, 1);
		this.setBlock(world, i + 4, j + 3, k + 13, Blocks.air, 5);
		this.setBlock(world, i + 4, j + 3, k + 14, Blocks.air, 5);
		this.setBlock(world, i + 4, j + 3, k + 15, Blocks.air, 5);
		this.setBlock(world, i + 4, j + 3, k + 16, Blocks.planks, 1);
		this.setBlock(world, i + 4, j + 3, k + 17, Blocks.sandstone, 0);
		this.setBlock(world, i + 4, j + 3, k + 18, Blocks.planks, 1);
		this.setBlock(world, i + 4, j + 4, k + 2, Blocks.sandstone, 0);
		this.setBlock(world, i + 4, j + 4, k + 3, Blocks.wooden_slab, 1);
		this.setBlock(world, i + 4, j + 4, k + 4, Blocks.planks, 1);
		this.setBlock(world, i + 4, j + 4, k + 5, Blocks.planks, 1);
		this.setBlock(world, i + 4, j + 4, k + 6, Blocks.planks, 1);
		this.setBlock(world, i + 4, j + 4, k + 7, Blocks.air, 3);
		this.setBlock(world, i + 4, j + 4, k + 12, Blocks.planks, 1);
		this.setBlock(world, i + 4, j + 4, k + 13, Blocks.air, 5);
		this.setBlock(world, i + 4, j + 4, k + 14, Blocks.air, 5);
		this.setBlock(world, i + 4, j + 4, k + 15, Blocks.air, 5);
		this.setBlock(world, i + 4, j + 4, k + 16, Blocks.planks, 1);
		this.setBlock(world, i + 4, j + 4, k + 17, Blocks.sandstone, 0);
		this.setBlock(world, i + 4, j + 4, k + 18, Blocks.sandstone, 0);
		this.setBlock(world, i + 4, j + 5, k + 2, Blocks.sandstone, 0);
		this.setBlock(world, i + 4, j + 5, k + 3, Blocks.planks, 1);
		this.setBlock(world, i + 4, j + 5, k + 4, Blocks.planks, 1);
		this.setBlock(world, i + 4, j + 5, k + 5, Blocks.planks, 1);
		this.setBlock(world, i + 4, j + 5, k + 6, Blocks.planks, 1);
		this.setBlock(world, i + 4, j + 5, k + 7, Blocks.air, 7);
		this.setBlock(world, i + 4, j + 5, k + 17, Blocks.sandstone, 0);
		this.setBlock(world, i + 4, j + 5, k + 18, Blocks.sandstone, 0);
		this.setBlock(world, i + 4, j + 6, k + 2, Blocks.planks, 1);
		this.setBlock(world, i + 4, j + 6, k + 3, Blocks.planks, 1);
		this.setBlock(world, i + 4, j + 6, k + 4, Blocks.planks, 1);
		this.setBlock(world, i + 4, j + 6, k + 5, Blocks.planks, 1);
		this.setBlock(world, i + 4, j + 6, k + 6, Blocks.planks, 1);
		this.setBlock(world, i + 4, j + 6, k + 7, Blocks.planks, 1);
		this.setBlock(world, i + 4, j + 6, k + 8, Blocks.planks, 1);
		this.setBlock(world, i + 4, j + 6, k + 9, Blocks.planks, 1);
		this.setBlock(world, i + 4, j + 6, k + 10, Blocks.planks, 1);
		this.setBlock(world, i + 4, j + 6, k + 11, Blocks.planks, 1);
		this.setBlock(world, i + 4, j + 6, k + 12, Blocks.planks, 1);
		this.setBlock(world, i + 4, j + 6, k + 13, Blocks.planks, 1);
		this.setBlock(world, i + 4, j + 6, k + 14, Blocks.planks, 1);
		this.setBlock(world, i + 4, j + 6, k + 15, Blocks.planks, 1);
		this.setBlock(world, i + 4, j + 6, k + 16, Blocks.planks, 1);
		this.setBlock(world, i + 4, j + 6, k + 17, Blocks.planks, 1);
		this.setBlock(world, i + 4, j + 6, k + 18, Blocks.planks, 1);
		this.setBlock(world, i + 4, j + 7, k + 2, Blocks.log, 2);
		this.setBlock(world, i + 4, j + 7, k + 3, Blocks.planks, 1);
		this.setBlock(world, i + 4, j + 7, k + 4, Blocks.planks, 1);
		this.setBlock(world, i + 4, j + 7, k + 5, Blocks.planks, 1);
		this.setBlock(world, i + 4, j + 7, k + 6, Blocks.planks, 1);
		this.setBlock(world, i + 4, j + 7, k + 7, Blocks.planks, 1);
		this.setBlock(world, i + 4, j + 7, k + 8, Blocks.planks, 1);
		this.setBlock(world, i + 4, j + 7, k + 9, Blocks.planks, 1);
		this.setBlock(world, i + 4, j + 7, k + 10, Blocks.planks, 1);
		this.setBlock(world, i + 4, j + 7, k + 11, Blocks.planks, 1);
		this.setBlock(world, i + 4, j + 7, k + 12, Blocks.planks, 1);
		this.setBlock(world, i + 4, j + 7, k + 13, Blocks.planks, 1);
		this.setBlock(world, i + 4, j + 7, k + 14, Blocks.planks, 1);
		this.setBlock(world, i + 4, j + 7, k + 15, Blocks.planks, 1);
		this.setBlock(world, i + 4, j + 7, k + 16, Blocks.planks, 1);
		this.setBlock(world, i + 4, j + 7, k + 17, Blocks.planks, 1);
		this.setBlock(world, i + 4, j + 7, k + 18, Blocks.log, 2);
		this.setBlock(world, i + 4, j + 8, k + 1, Blocks.air, 3);
		this.setBlock(world, i + 4, j + 8, k + 2, Blocks.air, 3);
		this.setBlock(world, i + 4, j + 8, k + 3, Blocks.air, 3);
		this.setBlock(world, i + 4, j + 8, k + 4, Blocks.air, 3);
		this.setBlock(world, i + 4, j + 8, k + 5, Blocks.air, 3);
		this.setBlock(world, i + 4, j + 8, k + 6, Blocks.air, 3);
		this.setBlock(world, i + 4, j + 8, k + 7, Blocks.air, 3);
		this.setBlock(world, i + 4, j + 8, k + 8, Blocks.air, 3);
		this.setBlock(world, i + 4, j + 8, k + 9, Blocks.air, 3);
		this.setBlock(world, i + 4, j + 8, k + 10, Blocks.air, 3);
		this.setBlock(world, i + 4, j + 8, k + 11, Blocks.air, 3);
		this.setBlock(world, i + 4, j + 8, k + 12, Blocks.air, 3);
		this.setBlock(world, i + 4, j + 8, k + 13, Blocks.air, 3);
		this.setBlock(world, i + 4, j + 8, k + 14, Blocks.air, 3);
		this.setBlock(world, i + 4, j + 8, k + 15, Blocks.air, 3);
		this.setBlock(world, i + 4, j + 8, k + 16, Blocks.air, 3);
		this.setBlock(world, i + 4, j + 8, k + 17, Blocks.air, 3);
		this.setBlock(world, i + 4, j + 8, k + 18, Blocks.air, 3);
		this.setBlock(world, i + 4, j + 8, k + 19, Blocks.air, 3);
		this.setBlock(world, i + 4, j + 9, k + 2, Blocks.air, 11);
		this.setBlock(world, i + 4, j + 9, k + 3, Blocks.air, 11);
		this.setBlock(world, i + 4, j + 9, k + 4, Blocks.air, 11);
		this.setBlock(world, i + 4, j + 9, k + 5, Blocks.air, 11);
		this.setBlock(world, i + 4, j + 9, k + 6, Blocks.air, 11);
		this.setBlock(world, i + 4, j + 9, k + 7, Blocks.air, 11);
		this.setBlock(world, i + 4, j + 9, k + 8, Blocks.air, 11);
		this.setBlock(world, i + 4, j + 9, k + 9, Blocks.air, 11);
		this.setBlock(world, i + 4, j + 9, k + 10, Blocks.air, 11);
		this.setBlock(world, i + 4, j + 9, k + 11, Blocks.air, 11);
		this.setBlock(world, i + 4, j + 9, k + 12, Blocks.air, 11);
		this.setBlock(world, i + 4, j + 9, k + 13, Blocks.sandstone, 0);
		this.setBlock(world, i + 4, j + 9, k + 14, Blocks.sandstone, 0);
		this.setBlock(world, i + 4, j + 9, k + 15, Blocks.sandstone, 0);
		this.setBlock(world, i + 4, j + 9, k + 16, Blocks.air, 11);
		this.setBlock(world, i + 4, j + 9, k + 17, Blocks.air, 11);
		this.setBlock(world, i + 4, j + 9, k + 18, Blocks.air, 11);
		this.setBlock(world, i + 4, j + 10, k + 13, Blocks.sandstone, 0);
		this.setBlock(world, i + 4, j + 10, k + 14, Blocks.sandstone, 0);
		this.setBlock(world, i + 4, j + 10, k + 15, Blocks.sandstone, 0);
		this.setBlock(world, i + 4, j + 11, k + 13, Blocks.sandstone, 0);
		this.setBlock(world, i + 4, j + 11, k + 14, Blocks.sandstone, 0);
		this.setBlock(world, i + 4, j + 11, k + 15, Blocks.sandstone, 0);
		this.setBlock(world, i + 4, j + 12, k + 13, Blocks.sandstone, 0);
		this.setBlock(world, i + 4, j + 12, k + 14, Blocks.sandstone, 0);
		this.setBlock(world, i + 4, j + 12, k + 15, Blocks.sandstone, 0);
		this.setBlock(world, i + 4, j + 13, k + 13, Blocks.sandstone, 0);
		this.setBlock(world, i + 4, j + 13, k + 14, Blocks.sandstone, 0);
		this.setBlock(world, i + 4, j + 13, k + 15, Blocks.sandstone, 0);
		this.setBlock(world, i + 4, j + 14, k + 13, Blocks.sandstone, 0);
		this.setBlock(world, i + 4, j + 14, k + 14, Blocks.sandstone, 0);
		this.setBlock(world, i + 4, j + 14, k + 15, Blocks.sandstone, 0);
		this.setBlock(world, i + 4, j + 15, k + 13, Blocks.sandstone, 0);
		this.setBlock(world, i + 4, j + 15, k + 14, Blocks.sandstone, 0);
		this.setBlock(world, i + 4, j + 15, k + 15, Blocks.sandstone, 0);
		this.setBlock(world, i + 4, j + 16, k + 13, Blocks.stone_slab, 1);
		this.setBlock(world, i + 4, j + 16, k + 14, Blocks.stone_slab, 1);
		this.setBlock(world, i + 4, j + 16, k + 15, Blocks.stone_slab, 1);
		this.setBlock(world, i + 5, j + 0, k + 2, Blocks.cobblestone, 0);
		this.setBlock(world, i + 5, j + 0, k + 3, Blocks.cobblestone, 0);
		this.setBlock(world, i + 5, j + 0, k + 4, Blocks.cobblestone, 0);
		this.setBlock(world, i + 5, j + 0, k + 5, Blocks.cobblestone, 0);
		this.setBlock(world, i + 5, j + 0, k + 6, Blocks.cobblestone, 0);
		this.setBlock(world, i + 5, j + 0, k + 7, Blocks.cobblestone, 0);
		this.setBlock(world, i + 5, j + 0, k + 8, Blocks.cobblestone, 0);
		this.setBlock(world, i + 5, j + 0, k + 9, Blocks.cobblestone, 0);
		this.setBlock(world, i + 5, j + 0, k + 10, Blocks.cobblestone, 0);
		this.setBlock(world, i + 5, j + 0, k + 11, Blocks.cobblestone, 0);
		this.setBlock(world, i + 5, j + 0, k + 12, Blocks.cobblestone, 0);
		this.setBlock(world, i + 5, j + 0, k + 13, Blocks.cobblestone, 0);
		this.setBlock(world, i + 5, j + 0, k + 14, Blocks.cobblestone, 0);
		this.setBlock(world, i + 5, j + 0, k + 15, Blocks.cobblestone, 0);
		this.setBlock(world, i + 5, j + 0, k + 16, Blocks.cobblestone, 0);
		this.setBlock(world, i + 5, j + 0, k + 17, Blocks.cobblestone, 0);
		this.setBlock(world, i + 5, j + 0, k + 18, Blocks.cobblestone, 0);
		this.setBlock(world, i + 5, j + 0, k + 19, Blocks.planks, 0);
		this.setBlock(world, i + 5, j + 0, k + 20, Blocks.planks, 0);
		this.setBlock(world, i + 5, j + 0, k + 21, Blocks.planks, 0);
		this.setBlock(world, i + 5, j + 0, k + 22, Blocks.planks, 0);
		this.setBlock(world, i + 5, j + 0, k + 23, Blocks.planks, 0);
		this.setBlock(world, i + 5, j + 0, k + 24, Blocks.planks, 0);
		this.setBlock(world, i + 5, j + 0, k + 25, Blocks.planks, 0);
		this.setBlock(world, i + 5, j + 1, k + 2, Blocks.sandstone, 0);
		this.setBlock(world, i + 5, j + 1, k + 3, Blocks.stone_slab, 3);
		this.setBlock(world, i + 5, j + 1, k + 4, Blocks.stone_slab, 3);
		this.setBlock(world, i + 5, j + 1, k + 5, Blocks.planks, 1);
		this.setBlock(world, i + 5, j + 1, k + 6, Blocks.stone_slab, 3);
		this.setBlock(world, i + 5, j + 1, k + 7, Blocks.stone_slab, 3);
		this.setBlock(world, i + 5, j + 1, k + 8, Blocks.stone_slab, 3);
		this.setBlock(world, i + 5, j + 1, k + 9, Blocks.planks, 1);
		this.setBlock(world, i + 5, j + 1, k + 10, Blocks.stone_stairs, 3);
		this.setBlock(world, i + 5, j + 1, k + 11, Blocks.stone_slab, 3);
		this.setBlock(world, i + 5, j + 1, k + 12, Blocks.stone_slab, 3);
		this.setBlock(world, i + 5, j + 1, k + 13, Blocks.stone_slab, 3);
		this.setBlock(world, i + 5, j + 1, k + 14, Blocks.stone_slab, 3);
		this.setBlock(world, i + 5, j + 1, k + 15, Blocks.stone_slab, 3);
		this.setBlock(world, i + 5, j + 1, k + 16, Blocks.stone_slab, 3);
		this.setBlock(world, i + 5, j + 1, k + 17, Blocks.stone_slab, 3);
		this.setBlock(world, i + 5, j + 1, k + 18, Blocks.sandstone, 0);
		this.setBlock(world, i + 5, j + 1, k + 21, Blocks.spruce_stairs, 6);
		this.setBlock(world, i + 5, j + 1, k + 22, Blocks.spruce_stairs, 5);
		this.setBlock(world, i + 5, j + 1, k + 23, Blocks.spruce_stairs, 2);
		this.setBlock(world, i + 5, j + 1, k + 25, Blocks.fence, 0);
		this.setBlock(world, i + 5, j + 2, k + 2, Blocks.air, 12);
		this.setBlock(world, i + 5, j + 2, k + 5, Blocks.jukebox, 0);
		this.setBlock(world, i + 5, j + 2, k + 8, Blocks.air, 6);
		this.setBlock(world, i + 5, j + 2, k + 9, Blocks.air, 3);
		this.setBlock(world, i + 5, j + 2, k + 18, Blocks.air, 12);
		this.setBlock(world, i + 5, j + 3, k + 2, Blocks.air, 12);
		this.setBlock(world, i + 5, j + 3, k + 5, Blocks.planks, 1);
		this.setBlock(world, i + 5, j + 3, k + 7, Blocks.air, 6);
		this.setBlock(world, i + 5, j + 3, k + 8, Blocks.air, 3);
		this.setBlock(world, i + 5, j + 3, k + 18, Blocks.air, 12);
		this.setBlock(world, i + 5, j + 4, k + 2, Blocks.sandstone, 0);
		this.setBlock(world, i + 5, j + 4, k + 3, Blocks.planks, 1);
		this.setBlock(world, i + 5, j + 4, k + 4, Blocks.planks, 1);
		this.setBlock(world, i + 5, j + 4, k + 5, Blocks.planks, 1);
		this.setBlock(world, i + 5, j + 4, k + 6, Blocks.planks, 1);
		this.setBlock(world, i + 5, j + 4, k + 7, Blocks.air, 3);
		this.setBlock(world, i + 5, j + 4, k + 18, Blocks.sandstone, 0);
		this.setBlock(world, i + 5, j + 5, k + 0, Blocks.air, 3);
		this.setBlock(world, i + 5, j + 5, k + 1, Blocks.air, 7);
		this.setBlock(world, i + 5, j + 5, k + 2, Blocks.sandstone, 0);
		this.setBlock(world, i + 5, j + 5, k + 18, Blocks.sandstone, 0);
		this.setBlock(world, i + 5, j + 6, k + 1, Blocks.air, 3);
		this.setBlock(world, i + 5, j + 6, k + 2, Blocks.planks, 5);
		this.setBlock(world, i + 5, j + 6, k + 9, Blocks.planks, 1);
		this.setBlock(world, i + 5, j + 6, k + 10, Blocks.planks, 1);
		this.setBlock(world, i + 5, j + 6, k + 11, Blocks.planks, 1);
		this.setBlock(world, i + 5, j + 6, k + 12, Blocks.planks, 1);
		this.setBlock(world, i + 5, j + 6, k + 13, Blocks.planks, 1);
		this.setBlock(world, i + 5, j + 6, k + 14, Blocks.planks, 1);
		this.setBlock(world, i + 5, j + 6, k + 15, Blocks.planks, 1);
		this.setBlock(world, i + 5, j + 6, k + 16, Blocks.planks, 1);
		this.setBlock(world, i + 5, j + 6, k + 17, Blocks.planks, 1);
		this.setBlock(world, i + 5, j + 6, k + 18, Blocks.planks, 5);
		this.setBlock(world, i + 5, j + 7, k + 2, Blocks.planks, 1);
		this.setBlock(world, i + 5, j + 7, k + 7, Blocks.planks, 1);
		this.setBlock(world, i + 5, j + 7, k + 8, Blocks.planks, 1);
		this.setBlock(world, i + 5, j + 7, k + 9, Blocks.planks, 1);
		this.setBlock(world, i + 5, j + 7, k + 10, Blocks.planks, 1);
		this.setBlock(world, i + 5, j + 7, k + 11, Blocks.planks, 1);
		this.setBlock(world, i + 5, j + 7, k + 12, Blocks.planks, 1);
		this.setBlock(world, i + 5, j + 7, k + 13, Blocks.planks, 1);
		this.setBlock(world, i + 5, j + 7, k + 14, Blocks.planks, 1);
		this.setBlock(world, i + 5, j + 7, k + 15, Blocks.planks, 1);
		this.setBlock(world, i + 5, j + 7, k + 16, Blocks.planks, 1);
		this.setBlock(world, i + 5, j + 7, k + 17, Blocks.planks, 1);
		this.setBlock(world, i + 5, j + 7, k + 18, Blocks.planks, 1);
		this.setBlock(world, i + 5, j + 8, k + 2, Blocks.planks, 5);
		this.setBlock(world, i + 5, j + 8, k + 3, Blocks.planks, 1);
		this.setBlock(world, i + 5, j + 8, k + 4, Blocks.planks, 1);
		this.setBlock(world, i + 5, j + 8, k + 5, Blocks.planks, 1);
		this.setBlock(world, i + 5, j + 8, k + 6, Blocks.planks, 1);
		this.setBlock(world, i + 5, j + 8, k + 7, Blocks.planks, 1);
		this.setBlock(world, i + 5, j + 8, k + 8, Blocks.planks, 1);
		this.setBlock(world, i + 5, j + 8, k + 9, Blocks.planks, 1);
		this.setBlock(world, i + 5, j + 8, k + 10, Blocks.planks, 1);
		this.setBlock(world, i + 5, j + 8, k + 11, Blocks.planks, 1);
		this.setBlock(world, i + 5, j + 8, k + 12, Blocks.planks, 1);
		this.setBlock(world, i + 5, j + 8, k + 13, Blocks.planks, 1);
		this.setBlock(world, i + 5, j + 8, k + 14, Blocks.planks, 1);
		this.setBlock(world, i + 5, j + 8, k + 15, Blocks.planks, 1);
		this.setBlock(world, i + 5, j + 8, k + 16, Blocks.planks, 1);
		this.setBlock(world, i + 5, j + 8, k + 17, Blocks.planks, 1);
		this.setBlock(world, i + 5, j + 8, k + 18, Blocks.planks, 5);
		this.setBlock(world, i + 5, j + 9, k + 1, Blocks.air, 3);
		this.setBlock(world, i + 5, j + 9, k + 2, Blocks.air, 3);
		this.setBlock(world, i + 5, j + 9, k + 3, Blocks.air, 3);
		this.setBlock(world, i + 5, j + 9, k + 4, Blocks.air, 3);
		this.setBlock(world, i + 5, j + 9, k + 5, Blocks.air, 3);
		this.setBlock(world, i + 5, j + 9, k + 6, Blocks.air, 3);
		this.setBlock(world, i + 5, j + 9, k + 7, Blocks.air, 3);
		this.setBlock(world, i + 5, j + 9, k + 8, Blocks.air, 3);
		this.setBlock(world, i + 5, j + 9, k + 9, Blocks.air, 3);
		this.setBlock(world, i + 5, j + 9, k + 10, Blocks.air, 3);
		this.setBlock(world, i + 5, j + 9, k + 11, Blocks.air, 3);
		this.setBlock(world, i + 5, j + 9, k + 12, Blocks.air, 3);
		this.setBlock(world, i + 5, j + 9, k + 13, Blocks.air, 3);
		this.setBlock(world, i + 5, j + 9, k + 14, Blocks.air, 3);
		this.setBlock(world, i + 5, j + 9, k + 15, Blocks.air, 3);
		this.setBlock(world, i + 5, j + 9, k + 16, Blocks.air, 3);
		this.setBlock(world, i + 5, j + 9, k + 17, Blocks.air, 3);
		this.setBlock(world, i + 5, j + 9, k + 18, Blocks.air, 3);
		this.setBlock(world, i + 5, j + 9, k + 19, Blocks.air, 3);
		this.setBlock(world, i + 5, j + 10, k + 1, Blocks.air, 3);
		this.setBlock(world, i + 5, j + 10, k + 2, Blocks.air, 3);
		this.setBlock(world, i + 5, j + 10, k + 3, Blocks.air, 3);
		this.setBlock(world, i + 5, j + 10, k + 4, Blocks.air, 3);
		this.setBlock(world, i + 5, j + 10, k + 5, Blocks.air, 3);
		this.setBlock(world, i + 5, j + 10, k + 6, Blocks.air, 3);
		this.setBlock(world, i + 5, j + 10, k + 7, Blocks.air, 3);
		this.setBlock(world, i + 5, j + 10, k + 8, Blocks.air, 3);
		this.setBlock(world, i + 5, j + 10, k + 9, Blocks.air, 3);
		this.setBlock(world, i + 5, j + 10, k + 10, Blocks.air, 3);
		this.setBlock(world, i + 5, j + 10, k + 11, Blocks.air, 3);
		this.setBlock(world, i + 5, j + 10, k + 12, Blocks.air, 3);
		this.setBlock(world, i + 5, j + 10, k + 13, Blocks.air, 3);
		this.setBlock(world, i + 5, j + 10, k + 14, Blocks.air, 3);
		this.setBlock(world, i + 5, j + 10, k + 15, Blocks.air, 3);
		this.setBlock(world, i + 5, j + 10, k + 16, Blocks.air, 3);
		this.setBlock(world, i + 5, j + 10, k + 17, Blocks.air, 3);
		this.setBlock(world, i + 5, j + 10, k + 18, Blocks.air, 3);
		this.setBlock(world, i + 5, j + 10, k + 19, Blocks.air, 3);
		this.setBlock(world, i + 5, j + 11, k + 2, Blocks.air, 11);
		this.setBlock(world, i + 5, j + 11, k + 3, Blocks.air, 11);
		this.setBlock(world, i + 5, j + 11, k + 4, Blocks.air, 11);
		this.setBlock(world, i + 5, j + 11, k + 5, Blocks.air, 11);
		this.setBlock(world, i + 5, j + 11, k + 6, Blocks.air, 11);
		this.setBlock(world, i + 5, j + 11, k + 7, Blocks.air, 11);
		this.setBlock(world, i + 5, j + 11, k + 8, Blocks.air, 11);
		this.setBlock(world, i + 5, j + 11, k + 9, Blocks.air, 11);
		this.setBlock(world, i + 5, j + 11, k + 10, Blocks.air, 11);
		this.setBlock(world, i + 5, j + 11, k + 11, Blocks.air, 11);
		this.setBlock(world, i + 5, j + 11, k + 12, Blocks.air, 11);
		this.setBlock(world, i + 5, j + 11, k + 13, Blocks.sandstone, 0);
		this.setBlock(world, i + 5, j + 11, k + 14, Blocks.sandstone, 0);
		this.setBlock(world, i + 5, j + 11, k + 15, Blocks.sandstone, 0);
		this.setBlock(world, i + 5, j + 11, k + 16, Blocks.air, 11);
		this.setBlock(world, i + 5, j + 11, k + 17, Blocks.air, 11);
		this.setBlock(world, i + 5, j + 11, k + 18, Blocks.air, 11);
		this.setBlock(world, i + 5, j + 12, k + 13, Blocks.sandstone, 0);
		this.setBlock(world, i + 5, j + 12, k + 14, Blocks.sandstone, 0);
		this.setBlock(world, i + 5, j + 12, k + 15, Blocks.sandstone, 0);
		this.setBlock(world, i + 5, j + 13, k + 13, Blocks.sandstone, 0);
		this.setBlock(world, i + 5, j + 13, k + 15, Blocks.sandstone, 0);
		this.setBlock(world, i + 5, j + 14, k + 13, Blocks.sandstone, 0);
		this.setBlock(world, i + 5, j + 14, k + 14, Blocks.sandstone, 0);
		this.setBlock(world, i + 5, j + 14, k + 15, Blocks.sandstone, 0);
		this.setBlock(world, i + 5, j + 15, k + 13, Blocks.sandstone, 0);
		this.setBlock(world, i + 5, j + 15, k + 15, Blocks.sandstone, 0);
		this.setBlock(world, i + 5, j + 16, k + 13, Blocks.stone_slab, 1);
		this.setBlock(world, i + 5, j + 16, k + 14, Blocks.stone_slab, 1);
		this.setBlock(world, i + 5, j + 16, k + 15, Blocks.stone_slab, 1);
		this.setBlock(world, i + 6, j + 0, k + 2, Blocks.cobblestone, 0);
		this.setBlock(world, i + 6, j + 0, k + 3, Blocks.cobblestone, 0);
		this.setBlock(world, i + 6, j + 0, k + 4, Blocks.cobblestone, 0);
		this.setBlock(world, i + 6, j + 0, k + 5, Blocks.cobblestone, 0);
		this.setBlock(world, i + 6, j + 0, k + 6, Blocks.cobblestone, 0);
		this.setBlock(world, i + 6, j + 0, k + 7, Blocks.cobblestone, 0);
		this.setBlock(world, i + 6, j + 0, k + 8, Blocks.cobblestone, 0);
		this.setBlock(world, i + 6, j + 0, k + 9, Blocks.cobblestone, 0);
		this.setBlock(world, i + 6, j + 0, k + 10, Blocks.cobblestone, 0);
		this.setBlock(world, i + 6, j + 0, k + 11, Blocks.cobblestone, 0);
		this.setBlock(world, i + 6, j + 0, k + 12, Blocks.cobblestone, 0);
		this.setBlock(world, i + 6, j + 0, k + 13, Blocks.cobblestone, 0);
		this.setBlock(world, i + 6, j + 0, k + 14, Blocks.cobblestone, 0);
		this.setBlock(world, i + 6, j + 0, k + 15, Blocks.cobblestone, 0);
		this.setBlock(world, i + 6, j + 0, k + 16, Blocks.cobblestone, 0);
		this.setBlock(world, i + 6, j + 0, k + 17, Blocks.cobblestone, 0);
		this.setBlock(world, i + 6, j + 0, k + 18, Blocks.cobblestone, 0);
		this.setBlock(world, i + 6, j + 0, k + 19, Blocks.planks, 0);
		this.setBlock(world, i + 6, j + 0, k + 20, Blocks.planks, 0);
		this.setBlock(world, i + 6, j + 0, k + 21, Blocks.planks, 0);
		this.setBlock(world, i + 6, j + 0, k + 22, Blocks.planks, 0);
		this.setBlock(world, i + 6, j + 0, k + 23, Blocks.planks, 0);
		this.setBlock(world, i + 6, j + 0, k + 24, Blocks.planks, 0);
		this.setBlock(world, i + 6, j + 0, k + 25, Blocks.planks, 0);
		this.setBlock(world, i + 6, j + 0, k + 26, Blocks.planks, 0);
		this.setBlock(world, i + 6, j + 1, k + 2, Blocks.sandstone, 0);
		this.setBlock(world, i + 6, j + 1, k + 3, Blocks.stone_slab, 3);
		this.setBlock(world, i + 6, j + 1, k + 4, Blocks.stone_slab, 3);
		this.setBlock(world, i + 6, j + 1, k + 5, Blocks.stone_slab, 3);
		this.setBlock(world, i + 6, j + 1, k + 6, Blocks.stone_slab, 3);
		this.setBlock(world, i + 6, j + 1, k + 7, Blocks.stone_slab, 3);
		this.setBlock(world, i + 6, j + 1, k + 8, Blocks.stone_slab, 3);
		this.setBlock(world, i + 6, j + 1, k + 9, Blocks.stone_slab, 3);
		this.setBlock(world, i + 6, j + 1, k + 10, Blocks.stone_slab, 3);
		this.setBlock(world, i + 6, j + 1, k + 11, Blocks.stone_slab, 3);
		this.setBlock(world, i + 6, j + 1, k + 12, Blocks.stone_stairs, 0);
		this.setBlock(world, i + 6, j + 1, k + 13, Blocks.stone_stairs, 0);
		this.setBlock(world, i + 6, j + 1, k + 14, Blocks.stone_stairs, 0);
		this.setBlock(world, i + 6, j + 1, k + 15, Blocks.stone_stairs, 0);
		this.setBlock(world, i + 6, j + 1, k + 16, Blocks.stone_slab, 3);
		this.setBlock(world, i + 6, j + 1, k + 17, Blocks.stone_slab, 3);
		this.setBlock(world, i + 6, j + 1, k + 18, Blocks.planks, 1);
		this.setBlock(world, i + 6, j + 1, k + 25, Blocks.fence, 0);
		this.setBlock(world, i + 6, j + 1, k + 26, Blocks.fence, 0);
		this.setBlock(world, i + 6, j + 2, k + 2, Blocks.planks, 1);
		this.setBlock(world, i + 6, j + 2, k + 18, Blocks.planks, 1);
		this.setBlock(world, i + 6, j + 3, k + 2, Blocks.planks, 1);
		this.setBlock(world, i + 6, j + 3, k + 18, Blocks.planks, 1);
		this.setBlock(world, i + 6, j + 4, k + 2, Blocks.sandstone, 0);
		this.setBlock(world, i + 6, j + 4, k + 3, Blocks.air, 5);
		this.setBlock(world, i + 6, j + 4, k + 4, Blocks.air, 5);
		this.setBlock(world, i + 6, j + 4, k + 18, Blocks.sandstone, 0);
		this.setBlock(world, i + 6, j + 5, k + 0, Blocks.air, 3);
		this.setBlock(world, i + 6, j + 5, k + 1, Blocks.air, 7);
		this.setBlock(world, i + 6, j + 5, k + 2, Blocks.sandstone, 0);
		// this.setBlock(world, i + 6, j + 5, k + 3, -122, 0);
		// this.setBlock(world, i + 6, j + 5, k + 4, -122, 0);
		this.setBlock(world, i + 6, j + 5, k + 5, Blocks.planks, 1);
		this.setBlock(world, i + 6, j + 5, k + 6, Blocks.planks, 1);
		this.setBlock(world, i + 6, j + 5, k + 7, Blocks.lit_redstone_lamp, 0);
		this.setBlock(world, i + 6, j + 5, k + 10, Blocks.lit_redstone_lamp, 0);
		this.setBlock(world, i + 6, j + 5, k + 13, Blocks.lit_redstone_lamp, 0);
		this.setBlock(world, i + 6, j + 5, k + 16, Blocks.lit_redstone_lamp, 0);
		this.setBlock(world, i + 6, j + 5, k + 18, Blocks.sandstone, 0);
		this.setBlock(world, i + 6, j + 6, k + 1, Blocks.air, 3);
		this.setBlock(world, i + 6, j + 6, k + 2, Blocks.planks, 1);
		this.setBlock(world, i + 6, j + 6, k + 5, Blocks.planks, 1);
		this.setBlock(world, i + 6, j + 6, k + 6, Blocks.planks, 1);
		this.setBlock(world, i + 6, j + 6, k + 7, Blocks.planks, 1);
		this.setBlock(world, i + 6, j + 6, k + 8, Blocks.planks, 1);
		this.setBlock(world, i + 6, j + 6, k + 9, Blocks.planks, 1);
		this.setBlock(world, i + 6, j + 6, k + 10, Blocks.lit_redstone_lamp, 0);
		this.setBlock(world, i + 6, j + 6, k + 11, Blocks.planks, 1);
		this.setBlock(world, i + 6, j + 6, k + 12, Blocks.planks, 1);
		this.setBlock(world, i + 6, j + 6, k + 13, Blocks.lit_redstone_lamp, 0);
		this.setBlock(world, i + 6, j + 6, k + 14, Blocks.planks, 1);
		this.setBlock(world, i + 6, j + 6, k + 15, Blocks.planks, 1);
		this.setBlock(world, i + 6, j + 6, k + 16, Blocks.lit_redstone_lamp, 0);
		this.setBlock(world, i + 6, j + 6, k + 17, Blocks.planks, 1);
		this.setBlock(world, i + 6, j + 6, k + 18, Blocks.planks, 1);
		this.setBlock(world, i + 6, j + 7, k + 2, Blocks.log, 2);
		this.setBlock(world, i + 6, j + 7, k + 5, Blocks.planks, 1);
		this.setBlock(world, i + 6, j + 7, k + 6, Blocks.planks, 1);
		this.setBlock(world, i + 6, j + 7, k + 17, Blocks.planks, 1);
		this.setBlock(world, i + 6, j + 7, k + 18, Blocks.log, 2);
		this.setBlock(world, i + 6, j + 8, k + 2, Blocks.planks, 1);
		this.setBlock(world, i + 6, j + 8, k + 5, Blocks.planks, 1);
		this.setBlock(world, i + 6, j + 8, k + 6, Blocks.planks, 1);
		this.setBlock(world, i + 6, j + 8, k + 15, Blocks.planks, 1);
		this.setBlock(world, i + 6, j + 8, k + 16, Blocks.wooden_slab, 9);
		this.setBlock(world, i + 6, j + 8, k + 17, Blocks.planks, 1);
		this.setBlock(world, i + 6, j + 8, k + 18, Blocks.planks, 1);
		this.setBlock(world, i + 6, j + 9, k + 2, Blocks.log, 2);
		this.setBlock(world, i + 6, j + 9, k + 3, Blocks.planks, 1);
		this.setBlock(world, i + 6, j + 9, k + 4, Blocks.planks, 1);
		this.setBlock(world, i + 6, j + 9, k + 5, Blocks.planks, 1);
		this.setBlock(world, i + 6, j + 9, k + 6, Blocks.planks, 1);
		this.setBlock(world, i + 6, j + 9, k + 7, Blocks.planks, 1);
		this.setBlock(world, i + 6, j + 9, k + 8, Blocks.planks, 1);
		this.setBlock(world, i + 6, j + 9, k + 9, Blocks.planks, 1);
		this.setBlock(world, i + 6, j + 9, k + 10, Blocks.planks, 1);
		this.setBlock(world, i + 6, j + 9, k + 11, Blocks.planks, 1);
		this.setBlock(world, i + 6, j + 9, k + 12, Blocks.planks, 1);
		this.setBlock(world, i + 6, j + 9, k + 13, Blocks.planks, 1);
		this.setBlock(world, i + 6, j + 9, k + 14, Blocks.planks, 1);
		this.setBlock(world, i + 6, j + 9, k + 15, Blocks.planks, 1);
		this.setBlock(world, i + 6, j + 9, k + 16, Blocks.planks, 1);
		this.setBlock(world, i + 6, j + 9, k + 17, Blocks.planks, 1);
		this.setBlock(world, i + 6, j + 9, k + 18, Blocks.log, 2);
		this.setBlock(world, i + 6, j + 10, k + 2, Blocks.planks, 1);
		this.setBlock(world, i + 6, j + 10, k + 3, Blocks.planks, 1);
		this.setBlock(world, i + 6, j + 10, k + 4, Blocks.planks, 1);
		this.setBlock(world, i + 6, j + 10, k + 5, Blocks.planks, 1);
		this.setBlock(world, i + 6, j + 10, k + 6, Blocks.planks, 1);
		this.setBlock(world, i + 6, j + 10, k + 7, Blocks.planks, 1);
		this.setBlock(world, i + 6, j + 10, k + 8, Blocks.planks, 1);
		this.setBlock(world, i + 6, j + 10, k + 9, Blocks.planks, 1);
		this.setBlock(world, i + 6, j + 10, k + 10, Blocks.planks, 1);
		this.setBlock(world, i + 6, j + 10, k + 11, Blocks.planks, 1);
		this.setBlock(world, i + 6, j + 10, k + 12, Blocks.planks, 1);
		this.setBlock(world, i + 6, j + 10, k + 13, Blocks.planks, 1);
		this.setBlock(world, i + 6, j + 10, k + 14, Blocks.planks, 1);
		this.setBlock(world, i + 6, j + 10, k + 15, Blocks.planks, 1);
		this.setBlock(world, i + 6, j + 10, k + 16, Blocks.planks, 1);
		this.setBlock(world, i + 6, j + 10, k + 17, Blocks.planks, 1);
		this.setBlock(world, i + 6, j + 10, k + 18, Blocks.planks, 1);
		this.setBlock(world, i + 6, j + 11, k + 1, Blocks.air, 3);
		this.setBlock(world, i + 6, j + 11, k + 2, Blocks.air, 3);
		this.setBlock(world, i + 6, j + 11, k + 3, Blocks.air, 3);
		this.setBlock(world, i + 6, j + 11, k + 4, Blocks.air, 3);
		this.setBlock(world, i + 6, j + 11, k + 5, Blocks.air, 3);
		this.setBlock(world, i + 6, j + 11, k + 6, Blocks.air, 3);
		this.setBlock(world, i + 6, j + 11, k + 7, Blocks.air, 3);
		this.setBlock(world, i + 6, j + 11, k + 8, Blocks.air, 3);
		this.setBlock(world, i + 6, j + 11, k + 9, Blocks.air, 3);
		this.setBlock(world, i + 6, j + 11, k + 10, Blocks.air, 3);
		this.setBlock(world, i + 6, j + 11, k + 11, Blocks.air, 3);
		this.setBlock(world, i + 6, j + 11, k + 12, Blocks.air, 3);
		this.setBlock(world, i + 6, j + 11, k + 13, Blocks.air, 3);
		this.setBlock(world, i + 6, j + 11, k + 14, Blocks.air, 3);
		this.setBlock(world, i + 6, j + 11, k + 15, Blocks.air, 3);
		this.setBlock(world, i + 6, j + 11, k + 16, Blocks.air, 3);
		this.setBlock(world, i + 6, j + 11, k + 17, Blocks.air, 3);
		this.setBlock(world, i + 6, j + 11, k + 18, Blocks.air, 3);
		this.setBlock(world, i + 6, j + 11, k + 19, Blocks.air, 3);
		this.setBlock(world, i + 6, j + 12, k + 1, Blocks.air, 3);
		this.setBlock(world, i + 6, j + 12, k + 2, Blocks.air, 3);
		this.setBlock(world, i + 6, j + 12, k + 3, Blocks.air, 3);
		this.setBlock(world, i + 6, j + 12, k + 4, Blocks.air, 3);
		this.setBlock(world, i + 6, j + 12, k + 5, Blocks.air, 3);
		this.setBlock(world, i + 6, j + 12, k + 6, Blocks.air, 3);
		this.setBlock(world, i + 6, j + 12, k + 7, Blocks.air, 3);
		this.setBlock(world, i + 6, j + 12, k + 8, Blocks.air, 3);
		this.setBlock(world, i + 6, j + 12, k + 9, Blocks.air, 3);
		this.setBlock(world, i + 6, j + 12, k + 10, Blocks.air, 3);
		this.setBlock(world, i + 6, j + 12, k + 11, Blocks.air, 3);
		this.setBlock(world, i + 6, j + 12, k + 12, Blocks.air, 3);
		this.setBlock(world, i + 6, j + 12, k + 13, Blocks.air, 3);
		this.setBlock(world, i + 6, j + 12, k + 15, Blocks.air, 3);
		this.setBlock(world, i + 6, j + 12, k + 16, Blocks.air, 3);
		this.setBlock(world, i + 6, j + 12, k + 17, Blocks.air, 3);
		this.setBlock(world, i + 6, j + 12, k + 18, Blocks.air, 3);
		this.setBlock(world, i + 6, j + 12, k + 19, Blocks.air, 3);
		this.setBlock(world, i + 6, j + 13, k + 2, Blocks.air, 11);
		this.setBlock(world, i + 6, j + 13, k + 3, Blocks.air, 11);
		this.setBlock(world, i + 6, j + 13, k + 4, Blocks.air, 11);
		this.setBlock(world, i + 6, j + 13, k + 5, Blocks.air, 11);
		this.setBlock(world, i + 6, j + 13, k + 6, Blocks.air, 11);
		this.setBlock(world, i + 6, j + 13, k + 7, Blocks.air, 11);
		this.setBlock(world, i + 6, j + 13, k + 8, Blocks.air, 11);
		this.setBlock(world, i + 6, j + 13, k + 9, Blocks.air, 11);
		this.setBlock(world, i + 6, j + 13, k + 10, Blocks.air, 11);
		this.setBlock(world, i + 6, j + 13, k + 11, Blocks.air, 11);
		this.setBlock(world, i + 6, j + 13, k + 12, Blocks.air, 11);
		this.setBlock(world, i + 6, j + 13, k + 13, Blocks.sandstone, 0);
		this.setBlock(world, i + 6, j + 13, k + 14, Blocks.stone_slab, 9);
		this.setBlock(world, i + 6, j + 13, k + 15, Blocks.sandstone, 0);
		this.setBlock(world, i + 6, j + 13, k + 16, Blocks.air, 11);
		this.setBlock(world, i + 6, j + 13, k + 17, Blocks.air, 11);
		this.setBlock(world, i + 6, j + 13, k + 18, Blocks.air, 11);
		this.setBlock(world, i + 7, j + 0, k + 2, Blocks.cobblestone, 0);
		this.setBlock(world, i + 7, j + 0, k + 3, Blocks.cobblestone, 0);
		this.setBlock(world, i + 7, j + 0, k + 4, Blocks.cobblestone, 0);
		this.setBlock(world, i + 7, j + 0, k + 5, Blocks.cobblestone, 0);
		this.setBlock(world, i + 7, j + 0, k + 6, Blocks.cobblestone, 0);
		this.setBlock(world, i + 7, j + 0, k + 7, Blocks.cobblestone, 0);
		this.setBlock(world, i + 7, j + 0, k + 8, Blocks.cobblestone, 0);
		this.setBlock(world, i + 7, j + 0, k + 9, Blocks.cobblestone, 0);
		this.setBlock(world, i + 7, j + 0, k + 10, Blocks.cobblestone, 0);
		this.setBlock(world, i + 7, j + 0, k + 11, Blocks.cobblestone, 0);
		this.setBlock(world, i + 7, j + 0, k + 12, Blocks.cobblestone, 0);
		this.setBlock(world, i + 7, j + 0, k + 13, Blocks.cobblestone, 0);
		this.setBlock(world, i + 7, j + 0, k + 14, Blocks.cobblestone, 0);
		this.setBlock(world, i + 7, j + 0, k + 15, Blocks.cobblestone, 0);
		this.setBlock(world, i + 7, j + 0, k + 16, Blocks.cobblestone, 0);
		this.setBlock(world, i + 7, j + 0, k + 17, Blocks.cobblestone, 0);
		this.setBlock(world, i + 7, j + 0, k + 18, Blocks.cobblestone, 0);
		this.setBlock(world, i + 7, j + 0, k + 19, Blocks.planks, 0);
		this.setBlock(world, i + 7, j + 0, k + 20, Blocks.planks, 0);
		this.setBlock(world, i + 7, j + 0, k + 21, Blocks.planks, 0);
		this.setBlock(world, i + 7, j + 0, k + 22, Blocks.planks, 0);
		this.setBlock(world, i + 7, j + 0, k + 23, Blocks.planks, 0);
		this.setBlock(world, i + 7, j + 0, k + 24, Blocks.planks, 0);
		this.setBlock(world, i + 7, j + 0, k + 25, Blocks.planks, 0);
		this.setBlock(world, i + 7, j + 0, k + 26, Blocks.planks, 0);
		this.setBlock(world, i + 7, j + 1, k + 2, Blocks.sandstone, 0);
		this.setBlock(world, i + 7, j + 1, k + 3, Blocks.stone_slab, 3);
		this.setBlock(world, i + 7, j + 1, k + 4, Blocks.stone_slab, 3);
		this.setBlock(world, i + 7, j + 1, k + 5, Blocks.stone_slab, 3);
		this.setBlock(world, i + 7, j + 1, k + 6, Blocks.stone_slab, 3);
		this.setBlock(world, i + 7, j + 1, k + 7, Blocks.stone_slab, 3);
		this.setBlock(world, i + 7, j + 1, k + 8, Blocks.stone_slab, 3);
		this.setBlock(world, i + 7, j + 1, k + 9, Blocks.stone_slab, 3);
		this.setBlock(world, i + 7, j + 1, k + 10, Blocks.stone_slab, 3);
		this.setBlock(world, i + 7, j + 1, k + 11, Blocks.stone_slab, 3);
		this.setBlock(world, i + 7, j + 1, k + 12, Blocks.planks, 1);
		this.setBlock(world, i + 7, j + 1, k + 13, Blocks.planks, 1);
		this.setBlock(world, i + 7, j + 1, k + 14, Blocks.planks, 1);
		this.setBlock(world, i + 7, j + 1, k + 15, Blocks.planks, 1);
		this.setBlock(world, i + 7, j + 1, k + 16, Blocks.stone_slab, 3);
		this.setBlock(world, i + 7, j + 1, k + 22, Blocks.spruce_stairs, 1);
		this.setBlock(world, i + 7, j + 1, k + 26, Blocks.fence, 0);
		this.setBlock(world, i + 7, j + 2, k + 2, Blocks.sandstone, 0);
		this.setBlock(world, i + 7, j + 2, k + 12, Blocks.planks, 1);
		this.setBlock(world, i + 7, j + 2, k + 13, Blocks.planks, 1);
		this.setBlock(world, i + 7, j + 2, k + 14, Blocks.planks, 1);
		this.setBlock(world, i + 7, j + 2, k + 15, Blocks.planks, 1);
		this.setBlock(world, i + 7, j + 3, k + 2, Blocks.sandstone, 0);
		this.setBlock(world, i + 7, j + 3, k + 18, Blocks.chest, 12);
		this.setBlock(world, i + 7, j + 4, k + 2, Blocks.sandstone, 0);
		this.setBlock(world, i + 7, j + 4, k + 18, Blocks.log, 8);
		this.setBlock(world, i + 7, j + 5, k + 0, Blocks.air, 3);
		this.setBlock(world, i + 7, j + 5, k + 1, Blocks.air, 7);
		this.setBlock(world, i + 7, j + 5, k + 2, Blocks.sandstone, 0);
		this.setBlock(world, i + 7, j + 5, k + 3, Blocks.air, 5);
		this.setBlock(world, i + 7, j + 5, k + 4, Blocks.air, 5);
		this.setBlock(world, i + 7, j + 5, k + 18, Blocks.sandstone, 0);
		this.setBlock(world, i + 7, j + 6, k + 1, Blocks.air, 3);
		this.setBlock(world, i + 7, j + 6, k + 2, Blocks.planks, 1);
		// this.setBlock(world, i + 7, j + 6, k + 3, -122, 0);
		// this.setBlock(world, i + 7, j + 6, k + 4, -122, 0);
		this.setBlock(world, i + 7, j + 6, k + 5, Blocks.planks, 1);
		this.setBlock(world, i + 7, j + 6, k + 6, Blocks.planks, 1);
		this.setBlock(world, i + 7, j + 6, k + 7, Blocks.planks, 1);
		this.setBlock(world, i + 7, j + 6, k + 8, Blocks.planks, 1);
		this.setBlock(world, i + 7, j + 6, k + 9, Blocks.planks, 1);
		this.setBlock(world, i + 7, j + 6, k + 10, Blocks.planks, 1);
		this.setBlock(world, i + 7, j + 6, k + 11, Blocks.planks, 1);
		this.setBlock(world, i + 7, j + 6, k + 12, Blocks.planks, 1);
		this.setBlock(world, i + 7, j + 6, k + 13, Blocks.planks, 1);
		this.setBlock(world, i + 7, j + 6, k + 14, Blocks.planks, 1);
		this.setBlock(world, i + 7, j + 6, k + 15, Blocks.planks, 1);
		this.setBlock(world, i + 7, j + 6, k + 16, Blocks.planks, 1);
		this.setBlock(world, i + 7, j + 6, k + 17, Blocks.planks, 1);
		this.setBlock(world, i + 7, j + 6, k + 18, Blocks.planks, 1);
		this.setBlock(world, i + 7, j + 7, k + 2, Blocks.log, 2);
		this.setBlock(world, i + 7, j + 7, k + 5, Blocks.planks, 1);
		this.setBlock(world, i + 7, j + 7, k + 6, Blocks.planks, 1);
		this.setBlock(world, i + 7, j + 7, k + 7, Blocks.chest, 3);
		this.setBlock(world, i + 7, j + 7, k + 15, Blocks.planks, 1);
		this.setBlock(world, i + 7, j + 7, k + 16, Blocks.planks, 1);
		this.setBlock(world, i + 7, j + 7, k + 17, Blocks.planks, 1);
		this.setBlock(world, i + 7, j + 7, k + 18, Blocks.log, 2);
		this.setBlock(world, i + 7, j + 8, k + 2, Blocks.planks, 1);
		this.setBlock(world, i + 7, j + 8, k + 5, Blocks.planks, 1);
		this.setBlock(world, i + 7, j + 8, k + 6, Blocks.planks, 1);
		this.setBlock(world, i + 7, j + 8, k + 15, Blocks.planks, 1);
		this.setBlock(world, i + 7, j + 8, k + 17, Blocks.planks, 1);
		this.setBlock(world, i + 7, j + 8, k + 18, Blocks.planks, 1);
		this.setBlock(world, i + 7, j + 9, k + 2, Blocks.log, 2);
		this.setBlock(world, i + 7, j + 9, k + 5, Blocks.planks, 1);
		this.setBlock(world, i + 7, j + 9, k + 6, Blocks.planks, 1);
		this.setBlock(world, i + 7, j + 9, k + 7, Blocks.planks, 1);
		this.setBlock(world, i + 7, j + 9, k + 8, Blocks.planks, 1);
		this.setBlock(world, i + 7, j + 9, k + 9, Blocks.planks, 1);
		this.setBlock(world, i + 7, j + 9, k + 10, Blocks.planks, 1);
		this.setBlock(world, i + 7, j + 9, k + 11, Blocks.planks, 1);
		this.setBlock(world, i + 7, j + 9, k + 12, Blocks.air, 1);
		this.setBlock(world, i + 7, j + 9, k + 13, Blocks.planks, 1);
		this.setBlock(world, i + 7, j + 9, k + 14, Blocks.planks, 1);
		this.setBlock(world, i + 7, j + 9, k + 15, Blocks.planks, 1);
		this.setBlock(world, i + 7, j + 9, k + 16, Blocks.planks, 1);
		this.setBlock(world, i + 7, j + 9, k + 18, Blocks.log, 2);
		this.setBlock(world, i + 7, j + 10, k + 2, Blocks.planks, 1);
		this.setBlock(world, i + 7, j + 10, k + 5, Blocks.planks, 1);
		this.setBlock(world, i + 7, j + 10, k + 6, Blocks.planks, 1);
		this.setBlock(world, i + 7, j + 10, k + 7, Blocks.planks, 1);
		this.setBlock(world, i + 7, j + 10, k + 8, Blocks.planks, 1);
		this.setBlock(world, i + 7, j + 10, k + 9, Blocks.planks, 1);
		this.setBlock(world, i + 7, j + 10, k + 10, Blocks.planks, 1);
		this.setBlock(world, i + 7, j + 10, k + 11, Blocks.planks, 1);
		this.setBlock(world, i + 7, j + 10, k + 13, Blocks.planks, 1);
		this.setBlock(world, i + 7, j + 10, k + 14, Blocks.planks, 1);
		this.setBlock(world, i + 7, j + 10, k + 17, Blocks.wooden_slab, 9);
		this.setBlock(world, i + 7, j + 10, k + 18, Blocks.planks, 1);
		this.setBlock(world, i + 7, j + 11, k + 2, Blocks.log, 2);
		this.setBlock(world, i + 7, j + 11, k + 3, Blocks.planks, 1);
		this.setBlock(world, i + 7, j + 11, k + 4, Blocks.planks, 1);
		this.setBlock(world, i + 7, j + 11, k + 5, Blocks.planks, 1);
		this.setBlock(world, i + 7, j + 11, k + 6, Blocks.planks, 1);
		this.setBlock(world, i + 7, j + 11, k + 7, Blocks.planks, 1);
		this.setBlock(world, i + 7, j + 11, k + 8, Blocks.planks, 1);
		this.setBlock(world, i + 7, j + 11, k + 9, Blocks.planks, 1);
		this.setBlock(world, i + 7, j + 11, k + 10, Blocks.planks, 1);
		this.setBlock(world, i + 7, j + 11, k + 11, Blocks.planks, 1);
		this.setBlock(world, i + 7, j + 11, k + 13, Blocks.planks, 1);
		this.setBlock(world, i + 7, j + 11, k + 15, Blocks.wooden_slab, 9);
		this.setBlock(world, i + 7, j + 11, k + 16, Blocks.planks, 1);
		this.setBlock(world, i + 7, j + 11, k + 17, Blocks.planks, 1);
		this.setBlock(world, i + 7, j + 11, k + 18, Blocks.log, 2);
		this.setBlock(world, i + 7, j + 12, k + 2, Blocks.planks, 1);
		this.setBlock(world, i + 7, j + 12, k + 3, Blocks.planks, 1);
		this.setBlock(world, i + 7, j + 12, k + 4, Blocks.planks, 1);
		this.setBlock(world, i + 7, j + 12, k + 5, Blocks.planks, 1);
		this.setBlock(world, i + 7, j + 12, k + 6, Blocks.planks, 1);
		this.setBlock(world, i + 7, j + 12, k + 7, Blocks.planks, 1);
		this.setBlock(world, i + 7, j + 12, k + 8, Blocks.planks, 1);
		this.setBlock(world, i + 7, j + 12, k + 9, Blocks.planks, 1);
		this.setBlock(world, i + 7, j + 12, k + 10, Blocks.planks, 1);
		this.setBlock(world, i + 7, j + 12, k + 11, Blocks.planks, 1);
		this.setBlock(world, i + 7, j + 12, k + 13, Blocks.planks, 1);
		this.setBlock(world, i + 7, j + 12, k + 14, Blocks.wooden_slab, 9);
		this.setBlock(world, i + 7, j + 12, k + 15, Blocks.planks, 1);
		this.setBlock(world, i + 7, j + 12, k + 16, Blocks.planks, 1);
		this.setBlock(world, i + 7, j + 12, k + 17, Blocks.planks, 1);
		this.setBlock(world, i + 7, j + 12, k + 18, Blocks.planks, 1);
		this.setBlock(world, i + 7, j + 13, k + 1, Blocks.air, 3);
		this.setBlock(world, i + 7, j + 13, k + 2, Blocks.air, 3);
		this.setBlock(world, i + 7, j + 13, k + 3, Blocks.air, 3);
		this.setBlock(world, i + 7, j + 13, k + 4, Blocks.air, 3);
		this.setBlock(world, i + 7, j + 13, k + 5, Blocks.air, 3);
		this.setBlock(world, i + 7, j + 13, k + 6, Blocks.air, 3);
		this.setBlock(world, i + 7, j + 13, k + 7, Blocks.air, 3);
		this.setBlock(world, i + 7, j + 13, k + 8, Blocks.air, 3);
		this.setBlock(world, i + 7, j + 13, k + 9, Blocks.air, 3);
		this.setBlock(world, i + 7, j + 13, k + 10, Blocks.air, 3);
		this.setBlock(world, i + 7, j + 13, k + 11, Blocks.air, 3);
		this.setBlock(world, i + 7, j + 13, k + 13, Blocks.air, 3);
		this.setBlock(world, i + 7, j + 13, k + 14, Blocks.air, 3);
		this.setBlock(world, i + 7, j + 13, k + 15, Blocks.air, 3);
		this.setBlock(world, i + 7, j + 13, k + 16, Blocks.air, 3);
		this.setBlock(world, i + 7, j + 13, k + 17, Blocks.air, 3);
		this.setBlock(world, i + 7, j + 13, k + 18, Blocks.air, 3);
		this.setBlock(world, i + 7, j + 13, k + 19, Blocks.air, 3);
		this.setBlock(world, i + 8, j + 0, k + 2, Blocks.cobblestone, 0);
		this.setBlock(world, i + 8, j + 0, k + 3, Blocks.cobblestone, 0);
		this.setBlock(world, i + 8, j + 0, k + 4, Blocks.cobblestone, 0);
		this.setBlock(world, i + 8, j + 0, k + 5, Blocks.cobblestone, 0);
		this.setBlock(world, i + 8, j + 0, k + 6, Blocks.cobblestone, 0);
		this.setBlock(world, i + 8, j + 0, k + 7, Blocks.cobblestone, 0);
		this.setBlock(world, i + 8, j + 0, k + 8, Blocks.cobblestone, 0);
		this.setBlock(world, i + 8, j + 0, k + 9, Blocks.cobblestone, 0);
		this.setBlock(world, i + 8, j + 0, k + 10, Blocks.cobblestone, 0);
		this.setBlock(world, i + 8, j + 0, k + 11, Blocks.cobblestone, 0);
		this.setBlock(world, i + 8, j + 0, k + 12, Blocks.cobblestone, 0);
		this.setBlock(world, i + 8, j + 0, k + 13, Blocks.cobblestone, 0);
		this.setBlock(world, i + 8, j + 0, k + 14, Blocks.cobblestone, 0);
		this.setBlock(world, i + 8, j + 0, k + 15, Blocks.cobblestone, 0);
		this.setBlock(world, i + 8, j + 0, k + 16, Blocks.cobblestone, 0);
		this.setBlock(world, i + 8, j + 0, k + 17, Blocks.cobblestone, 0);
		this.setBlock(world, i + 8, j + 0, k + 18, Blocks.cobblestone, 0);
		this.setBlock(world, i + 8, j + 0, k + 19, Blocks.planks, 0);
		this.setBlock(world, i + 8, j + 0, k + 20, Blocks.planks, 0);
		this.setBlock(world, i + 8, j + 0, k + 21, Blocks.planks, 0);
		this.setBlock(world, i + 8, j + 0, k + 22, Blocks.planks, 0);
		this.setBlock(world, i + 8, j + 0, k + 23, Blocks.planks, 0);
		this.setBlock(world, i + 8, j + 0, k + 24, Blocks.planks, 0);
		this.setBlock(world, i + 8, j + 0, k + 25, Blocks.planks, 0);
		this.setBlock(world, i + 8, j + 0, k + 26, Blocks.planks, 0);
		this.setBlock(world, i + 8, j + 1, k + 2, Blocks.planks, 1);
		this.setBlock(world, i + 8, j + 1, k + 3, Blocks.stone_slab, 3);
		this.setBlock(world, i + 8, j + 1, k + 4, Blocks.stone_slab, 3);
		this.setBlock(world, i + 8, j + 1, k + 5, Blocks.planks, 1);
		this.setBlock(world, i + 8, j + 1, k + 6, Blocks.planks, 1);
		this.setBlock(world, i + 8, j + 1, k + 7, Blocks.stone_slab, 3);
		this.setBlock(world, i + 8, j + 1, k + 8, Blocks.planks, 1);
		this.setBlock(world, i + 8, j + 1, k + 9, Blocks.planks, 1);
		this.setBlock(world, i + 8, j + 1, k + 10, Blocks.stone_slab, 3);
		this.setBlock(world, i + 8, j + 1, k + 11, Blocks.stone_slab, 3);
		this.setBlock(world, i + 8, j + 1, k + 12, Blocks.air, 1);
		this.setBlock(world, i + 8, j + 1, k + 13, Blocks.air, 1);
		this.setBlock(world, i + 8, j + 1, k + 14, Blocks.air, 2);
		this.setBlock(world, i + 8, j + 1, k + 15, Blocks.planks, 1);
		this.setBlock(world, i + 8, j + 1, k + 16, Blocks.stone_slab, 3);
		this.setBlock(world, i + 8, j + 1, k + 22, Blocks.spruce_stairs, 4);
		this.setBlock(world, i + 8, j + 1, k + 23, Blocks.spruce_stairs, 7);
		this.setBlock(world, i + 8, j + 1, k + 24, Blocks.spruce_stairs, 2);
		this.setBlock(world, i + 8, j + 1, k + 26, Blocks.fence, 0);
		this.setBlock(world, i + 8, j + 2, k + 2, Blocks.planks, 1);
		this.setBlock(world, i + 8, j + 2, k + 15, Blocks.planks, 1);
		this.setBlock(world, i + 8, j + 3, k + 2, Blocks.planks, 1);
		this.setBlock(world, i + 8, j + 3, k + 18, Blocks.chest, 12);
		this.setBlock(world, i + 8, j + 4, k + 2, Blocks.planks, 1);
		this.setBlock(world, i + 8, j + 4, k + 18, Blocks.log, 8);
		this.setBlock(world, i + 8, j + 5, k + 0, Blocks.air, 3);
		this.setBlock(world, i + 8, j + 5, k + 1, Blocks.air, 7);
		this.setBlock(world, i + 8, j + 5, k + 2, Blocks.planks, 1);
		this.setBlock(world, i + 8, j + 5, k + 18, Blocks.sandstone, 0);
		this.setBlock(world, i + 8, j + 6, k + 1, Blocks.air, 3);
		this.setBlock(world, i + 8, j + 6, k + 2, Blocks.planks, 5);
		this.setBlock(world, i + 8, j + 6, k + 3, Blocks.planks, 1);
		this.setBlock(world, i + 8, j + 6, k + 4, Blocks.planks, 1);
		this.setBlock(world, i + 8, j + 6, k + 5, Blocks.planks, 1);
		this.setBlock(world, i + 8, j + 6, k + 6, Blocks.planks, 1);
		this.setBlock(world, i + 8, j + 6, k + 7, Blocks.planks, 1);
		this.setBlock(world, i + 8, j + 6, k + 8, Blocks.planks, 1);
		this.setBlock(world, i + 8, j + 6, k + 9, Blocks.planks, 1);
		this.setBlock(world, i + 8, j + 6, k + 10, Blocks.planks, 1);
		this.setBlock(world, i + 8, j + 6, k + 11, Blocks.planks, 1);
		this.setBlock(world, i + 8, j + 6, k + 12, Blocks.planks, 1);
		this.setBlock(world, i + 8, j + 6, k + 13, Blocks.planks, 1);
		this.setBlock(world, i + 8, j + 6, k + 14, Blocks.planks, 1);
		this.setBlock(world, i + 8, j + 6, k + 15, Blocks.planks, 1);
		this.setBlock(world, i + 8, j + 6, k + 16, Blocks.planks, 1);
		this.setBlock(world, i + 8, j + 6, k + 17, Blocks.planks, 1);
		this.setBlock(world, i + 8, j + 6, k + 18, Blocks.planks, 5);
		this.setBlock(world, i + 8, j + 7, k + 2, Blocks.planks, 1);
		this.setBlock(world, i + 8, j + 7, k + 5, Blocks.air, 2);
		this.setBlock(world, i + 8, j + 7, k + 6, Blocks.planks, 1);
		this.setBlock(world, i + 8, j + 7, k + 7, Blocks.planks, 1);
		this.setBlock(world, i + 8, j + 7, k + 15, Blocks.planks, 1);
		this.setBlock(world, i + 8, j + 7, k + 16, Blocks.planks, 1);
		this.setBlock(world, i + 8, j + 7, k + 17, Blocks.planks, 1);
		this.setBlock(world, i + 8, j + 7, k + 18, Blocks.planks, 1);
		this.setBlock(world, i + 8, j + 8, k + 2, Blocks.planks, 5);
		this.setBlock(world, i + 8, j + 8, k + 6, Blocks.air, 2);
		this.setBlock(world, i + 8, j + 8, k + 7, Blocks.planks, 1);
		this.setBlock(world, i + 8, j + 8, k + 15, Blocks.planks, 1);
		this.setBlock(world, i + 8, j + 8, k + 17, Blocks.planks, 1);
		this.setBlock(world, i + 8, j + 8, k + 18, Blocks.planks, 5);
		this.setBlock(world, i + 8, j + 9, k + 2, Blocks.planks, 1);
		this.setBlock(world, i + 8, j + 9, k + 7, Blocks.wooden_slab, 1);
		this.setBlock(world, i + 8, j + 9, k + 8, Blocks.wooden_slab, 1);
		this.setBlock(world, i + 8, j + 9, k + 9, Blocks.wooden_slab, 1);
		this.setBlock(world, i + 8, j + 9, k + 10, Blocks.wooden_slab, 1);
		this.setBlock(world, i + 8, j + 9, k + 11, Blocks.wooden_slab, 1);
		this.setBlock(world, i + 8, j + 9, k + 12, Blocks.wooden_slab, 1);
		this.setBlock(world, i + 8, j + 9, k + 13, Blocks.wooden_slab, 1);
		this.setBlock(world, i + 8, j + 9, k + 14, Blocks.planks, 1);
		this.setBlock(world, i + 8, j + 9, k + 15, Blocks.planks, 1);
		this.setBlock(world, i + 8, j + 9, k + 16, Blocks.wooden_slab, 9);
		this.setBlock(world, i + 8, j + 9, k + 18, Blocks.planks, 1);
		this.setBlock(world, i + 8, j + 10, k + 2, Blocks.planks, 5);
		this.setBlock(world, i + 8, j + 10, k + 14, Blocks.planks, 1);
		this.setBlock(world, i + 8, j + 10, k + 15, Blocks.planks, 1);
		this.setBlock(world, i + 8, j + 10, k + 16, Blocks.planks, 1);
		this.setBlock(world, i + 8, j + 10, k + 17, Blocks.planks, 1);
		this.setBlock(world, i + 8, j + 10, k + 18, Blocks.planks, 5);
		this.setBlock(world, i + 8, j + 11, k + 2, Blocks.planks, 1);
		this.setBlock(world, i + 8, j + 11, k + 14, Blocks.planks, 1);
		this.setBlock(world, i + 8, j + 11, k + 15, Blocks.planks, 1);
		this.setBlock(world, i + 8, j + 11, k + 16, Blocks.planks, 1);
		this.setBlock(world, i + 8, j + 11, k + 17, Blocks.planks, 1);
		this.setBlock(world, i + 8, j + 11, k + 18, Blocks.planks, 1);
		this.setBlock(world, i + 8, j + 12, k + 2, Blocks.planks, 5);
		this.setBlock(world, i + 8, j + 12, k + 12, Blocks.planks, 1);
		this.setBlock(world, i + 8, j + 12, k + 13, Blocks.planks, 1);
		this.setBlock(world, i + 8, j + 12, k + 14, Blocks.planks, 1);
		this.setBlock(world, i + 8, j + 12, k + 15, Blocks.planks, 1);
		this.setBlock(world, i + 8, j + 12, k + 16, Blocks.planks, 1);
		this.setBlock(world, i + 8, j + 12, k + 17, Blocks.planks, 1);
		this.setBlock(world, i + 8, j + 12, k + 18, Blocks.planks, 5);
		this.setBlock(world, i + 8, j + 13, k + 1, Blocks.nether_brick_fence, 0);
		this.setBlock(world, i + 8, j + 13, k + 2, Blocks.log, 2);
		this.setBlock(world, i + 8, j + 13, k + 3, Blocks.planks, 1);
		this.setBlock(world, i + 8, j + 13, k + 4, Blocks.planks, 1);
		this.setBlock(world, i + 8, j + 13, k + 5, Blocks.planks, 1);
		this.setBlock(world, i + 8, j + 13, k + 6, Blocks.planks, 1);
		this.setBlock(world, i + 8, j + 13, k + 7, Blocks.planks, 1);
		this.setBlock(world, i + 8, j + 13, k + 8, Blocks.planks, 1);
		this.setBlock(world, i + 8, j + 13, k + 9, Blocks.planks, 1);
		this.setBlock(world, i + 8, j + 13, k + 10, Blocks.planks, 1);
		this.setBlock(world, i + 8, j + 13, k + 11, Blocks.planks, 1);
		this.setBlock(world, i + 8, j + 13, k + 12, Blocks.air, 3);
		this.setBlock(world, i + 8, j + 13, k + 13, Blocks.planks, 1);
		this.setBlock(world, i + 8, j + 13, k + 14, Blocks.planks, 1);
		this.setBlock(world, i + 8, j + 13, k + 15, Blocks.planks, 1);
		this.setBlock(world, i + 8, j + 13, k + 16, Blocks.planks, 1);
		this.setBlock(world, i + 8, j + 13, k + 17, Blocks.planks, 1);
		this.setBlock(world, i + 8, j + 13, k + 18, Blocks.log, 2);
		this.setBlock(world, i + 8, j + 13, k + 19, Blocks.nether_brick_fence, 0);
		this.setBlock(world, i + 8, j + 14, k + 1, Blocks.air, 3);
		this.setBlock(world, i + 8, j + 14, k + 2, Blocks.air, 3);
		this.setBlock(world, i + 8, j + 14, k + 3, Blocks.air, 3);
		this.setBlock(world, i + 8, j + 14, k + 4, Blocks.air, 3);
		this.setBlock(world, i + 8, j + 14, k + 5, Blocks.air, 3);
		this.setBlock(world, i + 8, j + 14, k + 6, Blocks.air, 3);
		this.setBlock(world, i + 8, j + 14, k + 7, Blocks.air, 3);
		this.setBlock(world, i + 8, j + 14, k + 8, Blocks.air, 3);
		this.setBlock(world, i + 8, j + 14, k + 9, Blocks.air, 3);
		this.setBlock(world, i + 8, j + 14, k + 10, Blocks.air, 3);
		this.setBlock(world, i + 8, j + 14, k + 11, Blocks.air, 3);
		this.setBlock(world, i + 8, j + 14, k + 12, Blocks.air, 3);
		this.setBlock(world, i + 8, j + 14, k + 13, Blocks.air, 3);
		this.setBlock(world, i + 8, j + 14, k + 14, Blocks.air, 3);
		this.setBlock(world, i + 8, j + 14, k + 15, Blocks.air, 3);
		this.setBlock(world, i + 8, j + 14, k + 16, Blocks.air, 3);
		this.setBlock(world, i + 8, j + 14, k + 17, Blocks.air, 3);
		this.setBlock(world, i + 8, j + 14, k + 18, Blocks.air, 3);
		this.setBlock(world, i + 8, j + 14, k + 19, Blocks.air, 3);
		this.setBlock(world, i + 9, j + 0, k + 1, Blocks.grass, 0);
		this.setBlock(world, i + 9, j + 0, k + 2, Blocks.cobblestone, 0);
		this.setBlock(world, i + 9, j + 0, k + 3, Blocks.cobblestone, 3); // stone_double_slab??
		this.setBlock(world, i + 9, j + 0, k + 4, Blocks.cobblestone, 0);
		this.setBlock(world, i + 9, j + 0, k + 5, Blocks.cobblestone, 0);
		this.setBlock(world, i + 9, j + 0, k + 6, Blocks.cobblestone, 0);
		this.setBlock(world, i + 9, j + 0, k + 7, Blocks.cobblestone, 0);
		this.setBlock(world, i + 9, j + 0, k + 8, Blocks.cobblestone, 0);
		this.setBlock(world, i + 9, j + 0, k + 9, Blocks.cobblestone, 0);
		this.setBlock(world, i + 9, j + 0, k + 10, Blocks.cobblestone, 0);
		this.setBlock(world, i + 9, j + 0, k + 11, Blocks.cobblestone, 0);
		this.setBlock(world, i + 9, j + 0, k + 12, Blocks.cobblestone, 0);
		this.setBlock(world, i + 9, j + 0, k + 13, Blocks.cobblestone, 0);
		this.setBlock(world, i + 9, j + 0, k + 14, Blocks.cobblestone, 0);
		this.setBlock(world, i + 9, j + 0, k + 15, Blocks.cobblestone, 0);
		this.setBlock(world, i + 9, j + 0, k + 16, Blocks.cobblestone, 0);
		this.setBlock(world, i + 9, j + 0, k + 17, Blocks.cobblestone, 0);
		this.setBlock(world, i + 9, j + 0, k + 18, Blocks.cobblestone, 0);
		this.setBlock(world, i + 9, j + 0, k + 19, Blocks.planks, 0);
		this.setBlock(world, i + 9, j + 0, k + 20, Blocks.planks, 0);
		this.setBlock(world, i + 9, j + 0, k + 21, Blocks.planks, 0);
		this.setBlock(world, i + 9, j + 0, k + 22, Blocks.planks, 0);
		this.setBlock(world, i + 9, j + 0, k + 23, Blocks.planks, 0);
		this.setBlock(world, i + 9, j + 0, k + 24, Blocks.planks, 0);
		this.setBlock(world, i + 9, j + 0, k + 25, Blocks.planks, 0);
		this.setBlock(world, i + 9, j + 0, k + 26, Blocks.planks, 0);
		this.setBlock(world, i + 9, j + 1, k + 4, Blocks.stone_slab, 3);
		this.setBlock(world, i + 9, j + 1, k + 5, Blocks.air, 3);
		this.setBlock(world, i + 9, j + 1, k + 6, Blocks.air, 2);
		this.setBlock(world, i + 9, j + 1, k + 7, Blocks.planks, 1);
		this.setBlock(world, i + 9, j + 1, k + 8, Blocks.air, 3);
		this.setBlock(world, i + 9, j + 1, k + 9, Blocks.air, 2);
		this.setBlock(world, i + 9, j + 1, k + 10, Blocks.stone_slab, 3);
		this.setBlock(world, i + 9, j + 1, k + 11, Blocks.stone_slab, 3);
		this.setBlock(world, i + 9, j + 1, k + 12, Blocks.stone_slab, 3);
		this.setBlock(world, i + 9, j + 1, k + 13, Blocks.stone_slab, 3);
		this.setBlock(world, i + 9, j + 1, k + 14, Blocks.air, 2);
		this.setBlock(world, i + 9, j + 1, k + 15, Blocks.planks, 1);
		this.setBlock(world, i + 9, j + 1, k + 16, Blocks.stone_slab, 3);
		this.setBlock(world, i + 9, j + 1, k + 17, Blocks.stone_slab, 3);
		this.setBlock(world, i + 9, j + 1, k + 18, Blocks.planks, 1);
		this.setBlock(world, i + 9, j + 1, k + 21, Blocks.spruce_stairs, 3);
		this.setBlock(world, i + 9, j + 1, k + 22, Blocks.spruce_stairs, 6);
		this.setBlock(world, i + 9, j + 1, k + 23, Blocks.spruce_stairs, 5);
		this.setBlock(world, i + 9, j + 1, k + 26, Blocks.fence, 0);
		this.setBlock(world, i + 9, j + 2, k + 5, Blocks.air, 7);
		this.setBlock(world, i + 9, j + 2, k + 6, Blocks.air, 6);
		this.setBlock(world, i + 9, j + 2, k + 7, Blocks.planks, 1);
		this.setBlock(world, i + 9, j + 2, k + 8, Blocks.air, 7);
		this.setBlock(world, i + 9, j + 2, k + 9, Blocks.air, 6);
		this.setBlock(world, i + 9, j + 2, k + 15, Blocks.planks, 1);
		this.setBlock(world, i + 9, j + 2, k + 18, Blocks.planks, 1);
		this.setBlock(world, i + 9, j + 3, k + 2, Blocks.chest, 12);
		this.setBlock(world, i + 9, j + 3, k + 18, Blocks.planks, 1);
		this.setBlock(world, i + 9, j + 4, k + 2, Blocks.log, 8);
		this.setBlock(world, i + 9, j + 4, k + 18, Blocks.planks, 1);
		this.setBlock(world, i + 9, j + 5, k + 0, Blocks.air, 3);
		this.setBlock(world, i + 9, j + 5, k + 1, Blocks.air, 7);
		this.setBlock(world, i + 9, j + 5, k + 2, Blocks.sandstone, 0);
		this.setBlock(world, i + 9, j + 5, k + 18, Blocks.planks, 1);
		this.setBlock(world, i + 9, j + 6, k + 1, Blocks.air, 3);
		this.setBlock(world, i + 9, j + 6, k + 2, Blocks.planks, 1);
		this.setBlock(world, i + 9, j + 6, k + 3, Blocks.planks, 1);
		this.setBlock(world, i + 9, j + 6, k + 4, Blocks.planks, 1);
		this.setBlock(world, i + 9, j + 6, k + 5, Blocks.planks, 1);
		this.setBlock(world, i + 9, j + 6, k + 6, Blocks.planks, 1);
		this.setBlock(world, i + 9, j + 6, k + 7, Blocks.planks, 1);
		this.setBlock(world, i + 9, j + 6, k + 8, Blocks.planks, 1);
		this.setBlock(world, i + 9, j + 6, k + 9, Blocks.planks, 1);
		this.setBlock(world, i + 9, j + 6, k + 10, Blocks.planks, 1);
		this.setBlock(world, i + 9, j + 6, k + 11, Blocks.planks, 1);
		this.setBlock(world, i + 9, j + 6, k + 12, Blocks.planks, 1);
		this.setBlock(world, i + 9, j + 6, k + 13, Blocks.planks, 1);
		this.setBlock(world, i + 9, j + 6, k + 14, Blocks.planks, 1);
		this.setBlock(world, i + 9, j + 6, k + 15, Blocks.planks, 1);
		this.setBlock(world, i + 9, j + 6, k + 16, Blocks.planks, 1);
		this.setBlock(world, i + 9, j + 6, k + 17, Blocks.planks, 1);
		this.setBlock(world, i + 9, j + 6, k + 18, Blocks.planks, 1);
		this.setBlock(world, i + 9, j + 7, k + 2, Blocks.log, 2);
		this.setBlock(world, i + 9, j + 7, k + 15, Blocks.planks, 1);
		this.setBlock(world, i + 9, j + 7, k + 16, Blocks.planks, 1);
		this.setBlock(world, i + 9, j + 7, k + 17, Blocks.planks, 1);
		this.setBlock(world, i + 9, j + 7, k + 18, Blocks.log, 2);
		this.setBlock(world, i + 9, j + 8, k + 2, Blocks.planks, 1);
		this.setBlock(world, i + 9, j + 8, k + 15, Blocks.planks, 1);
		this.setBlock(world, i + 9, j + 8, k + 16, Blocks.planks, 1);
		this.setBlock(world, i + 9, j + 8, k + 18, Blocks.planks, 1);
		this.setBlock(world, i + 9, j + 9, k + 2, Blocks.log, 2);
		this.setBlock(world, i + 9, j + 9, k + 5, Blocks.planks, 1);
		this.setBlock(world, i + 9, j + 9, k + 6, Blocks.wooden_slab, 1);
		this.setBlock(world, i + 9, j + 9, k + 7, Blocks.wooden_slab, 1);
		this.setBlock(world, i + 9, j + 9, k + 8, Blocks.planks, 1);
		this.setBlock(world, i + 9, j + 9, k + 9, Blocks.wooden_slab, 1);
		this.setBlock(world, i + 9, j + 9, k + 10, Blocks.wooden_slab, 1);
		this.setBlock(world, i + 9, j + 9, k + 11, Blocks.planks, 1);
		this.setBlock(world, i + 9, j + 9, k + 12, Blocks.wooden_slab, 1);
		this.setBlock(world, i + 9, j + 9, k + 13, Blocks.wooden_slab, 1);
		this.setBlock(world, i + 9, j + 9, k + 14, Blocks.planks, 1);
		this.setBlock(world, i + 9, j + 9, k + 15, Blocks.planks, 1);
		this.setBlock(world, i + 9, j + 9, k + 16, Blocks.planks, 1);
		this.setBlock(world, i + 9, j + 9, k + 17, Blocks.wooden_slab, 1);
		this.setBlock(world, i + 9, j + 9, k + 18, Blocks.log, 2);
		this.setBlock(world, i + 9, j + 10, k + 2, Blocks.planks, 1);
		this.setBlock(world, i + 9, j + 10, k + 5, Blocks.planks, 1);
		this.setBlock(world, i + 9, j + 10, k + 8, Blocks.planks, 1);
		this.setBlock(world, i + 9, j + 10, k + 11, Blocks.planks, 1);
		this.setBlock(world, i + 9, j + 10, k + 14, Blocks.planks, 1);
		this.setBlock(world, i + 9, j + 10, k + 15, Blocks.planks, 1);
		this.setBlock(world, i + 9, j + 10, k + 16, Blocks.planks, 1);
		this.setBlock(world, i + 9, j + 10, k + 17, Blocks.planks, 1);
		this.setBlock(world, i + 9, j + 10, k + 18, Blocks.planks, 1);
		this.setBlock(world, i + 9, j + 11, k + 2, Blocks.log, 2);
		this.setBlock(world, i + 9, j + 11, k + 3, Blocks.planks, 1);
		this.setBlock(world, i + 9, j + 11, k + 4, Blocks.planks, 1);
		this.setBlock(world, i + 9, j + 11, k + 5, Blocks.planks, 1);
		this.setBlock(world, i + 9, j + 11, k + 8, Blocks.planks, 1);
		this.setBlock(world, i + 9, j + 11, k + 11, Blocks.planks, 1);
		this.setBlock(world, i + 9, j + 11, k + 14, Blocks.planks, 1);
		this.setBlock(world, i + 9, j + 11, k + 15, Blocks.planks, 1);
		this.setBlock(world, i + 9, j + 11, k + 16, Blocks.planks, 1);
		this.setBlock(world, i + 9, j + 11, k + 17, Blocks.planks, 1);
		this.setBlock(world, i + 9, j + 11, k + 18, Blocks.log, 2);
		this.setBlock(world, i + 9, j + 12, k + 2, Blocks.planks, 1);
		this.setBlock(world, i + 9, j + 12, k + 3, Blocks.planks, 1);
		this.setBlock(world, i + 9, j + 12, k + 4, Blocks.planks, 1);
		this.setBlock(world, i + 9, j + 12, k + 5, Blocks.planks, 1);
		this.setBlock(world, i + 9, j + 12, k + 6, Blocks.planks, 1);
		this.setBlock(world, i + 9, j + 12, k + 7, Blocks.planks, 1);
		this.setBlock(world, i + 9, j + 12, k + 8, Blocks.planks, 1);
		this.setBlock(world, i + 9, j + 12, k + 9, Blocks.planks, 1);
		this.setBlock(world, i + 9, j + 12, k + 10, Blocks.planks, 1);
		this.setBlock(world, i + 9, j + 12, k + 11, Blocks.planks, 1);
		this.setBlock(world, i + 9, j + 12, k + 12, Blocks.planks, 1);
		this.setBlock(world, i + 9, j + 12, k + 13, Blocks.planks, 1);
		this.setBlock(world, i + 9, j + 12, k + 14, Blocks.planks, 1);
		this.setBlock(world, i + 9, j + 12, k + 15, Blocks.planks, 1);
		this.setBlock(world, i + 9, j + 12, k + 16, Blocks.planks, 1);
		this.setBlock(world, i + 9, j + 12, k + 17, Blocks.planks, 1);
		this.setBlock(world, i + 9, j + 12, k + 18, Blocks.planks, 1);
		this.setBlock(world, i + 9, j + 13, k + 1, Blocks.air, 3);
		this.setBlock(world, i + 9, j + 13, k + 2, Blocks.air, 3);
		this.setBlock(world, i + 9, j + 13, k + 3, Blocks.air, 3);
		this.setBlock(world, i + 9, j + 13, k + 4, Blocks.air, 3);
		this.setBlock(world, i + 9, j + 13, k + 5, Blocks.air, 3);
		this.setBlock(world, i + 9, j + 13, k + 6, Blocks.air, 3);
		this.setBlock(world, i + 9, j + 13, k + 7, Blocks.air, 3);
		this.setBlock(world, i + 9, j + 13, k + 8, Blocks.air, 3);
		this.setBlock(world, i + 9, j + 13, k + 9, Blocks.air, 3);
		this.setBlock(world, i + 9, j + 13, k + 10, Blocks.air, 3);
		this.setBlock(world, i + 9, j + 13, k + 11, Blocks.air, 3);
		this.setBlock(world, i + 9, j + 13, k + 12, Blocks.air, 3);
		this.setBlock(world, i + 9, j + 13, k + 13, Blocks.air, 3);
		this.setBlock(world, i + 9, j + 13, k + 14, Blocks.air, 3);
		this.setBlock(world, i + 9, j + 13, k + 15, Blocks.air, 3);
		this.setBlock(world, i + 9, j + 13, k + 16, Blocks.air, 3);
		this.setBlock(world, i + 9, j + 13, k + 17, Blocks.air, 3);
		this.setBlock(world, i + 9, j + 13, k + 18, Blocks.air, 3);
		this.setBlock(world, i + 9, j + 13, k + 19, Blocks.air, 3);
		this.setBlock(world, i + 10, j + 0, k + 1, Blocks.grass, 0);
		this.setBlock(world, i + 10, j + 0, k + 2, Blocks.cobblestone, 0);
		this.setBlock(world, i + 10, j + 0, k + 3, Blocks.cobblestone, 3); // stone_double_slab??
		this.setBlock(world, i + 10, j + 0, k + 4, Blocks.cobblestone, 0);
		this.setBlock(world, i + 10, j + 0, k + 5, Blocks.cobblestone, 0);
		this.setBlock(world, i + 10, j + 0, k + 6, Blocks.cobblestone, 0);
		this.setBlock(world, i + 10, j + 0, k + 7, Blocks.cobblestone, 0);
		this.setBlock(world, i + 10, j + 0, k + 8, Blocks.cobblestone, 0);
		this.setBlock(world, i + 10, j + 0, k + 9, Blocks.cobblestone, 0);
		this.setBlock(world, i + 10, j + 0, k + 10, Blocks.cobblestone, 0);
		this.setBlock(world, i + 10, j + 0, k + 11, Blocks.cobblestone, 0);
		this.setBlock(world, i + 10, j + 0, k + 12, Blocks.cobblestone, 0);
		this.setBlock(world, i + 10, j + 0, k + 13, Blocks.cobblestone, 0);
		this.setBlock(world, i + 10, j + 0, k + 14, Blocks.cobblestone, 0);
		this.setBlock(world, i + 10, j + 0, k + 15, Blocks.cobblestone, 0);
		this.setBlock(world, i + 10, j + 0, k + 16, Blocks.cobblestone, 0);
		this.setBlock(world, i + 10, j + 0, k + 17, Blocks.cobblestone, 0);
		this.setBlock(world, i + 10, j + 0, k + 18, Blocks.cobblestone, 0);
		this.setBlock(world, i + 10, j + 0, k + 19, Blocks.planks, 0);
		this.setBlock(world, i + 10, j + 0, k + 20, Blocks.planks, 0);
		this.setBlock(world, i + 10, j + 0, k + 21, Blocks.planks, 0);
		this.setBlock(world, i + 10, j + 0, k + 22, Blocks.planks, 0);
		this.setBlock(world, i + 10, j + 0, k + 23, Blocks.planks, 0);
		this.setBlock(world, i + 10, j + 0, k + 24, Blocks.planks, 0);
		this.setBlock(world, i + 10, j + 0, k + 25, Blocks.planks, 0);
		this.setBlock(world, i + 10, j + 0, k + 26, Blocks.planks, 0);
		this.setBlock(world, i + 10, j + 1, k + 4, Blocks.stone_slab, 3);
		this.setBlock(world, i + 10, j + 1, k + 5, Blocks.planks, 1);
		this.setBlock(world, i + 10, j + 1, k + 6, Blocks.planks, 1);
		this.setBlock(world, i + 10, j + 1, k + 7, Blocks.stone_slab, 3);
		this.setBlock(world, i + 10, j + 1, k + 8, Blocks.planks, 1);
		this.setBlock(world, i + 10, j + 1, k + 9, Blocks.planks, 1);
		this.setBlock(world, i + 10, j + 1, k + 10, Blocks.stone_slab, 3);
		this.setBlock(world, i + 10, j + 1, k + 11, Blocks.stone_slab, 3);
		this.setBlock(world, i + 10, j + 1, k + 12, Blocks.stone_slab, 3);
		this.setBlock(world, i + 10, j + 1, k + 13, Blocks.stone_slab, 3);
		this.setBlock(world, i + 10, j + 1, k + 14, Blocks.stone_slab, 3);
		this.setBlock(world, i + 10, j + 1, k + 15, Blocks.stone_slab, 3);
		this.setBlock(world, i + 10, j + 1, k + 16, Blocks.stone_slab, 3);
		this.setBlock(world, i + 10, j + 1, k + 17, Blocks.stone_slab, 3);
		this.setBlock(world, i + 10, j + 1, k + 18, Blocks.sandstone, 0);
		this.setBlock(world, i + 10, j + 1, k + 23, Blocks.spruce_stairs, 0);
		this.setBlock(world, i + 10, j + 1, k + 25, Blocks.fence, 0);
		this.setBlock(world, i + 10, j + 1, k + 26, Blocks.fence, 0);
		this.setBlock(world, i + 10, j + 2, k + 18, Blocks.air, 12);
		this.setBlock(world, i + 10, j + 3, k + 2, Blocks.chest, 12);
		this.setBlock(world, i + 10, j + 3, k + 18, Blocks.air, 12);
		this.setBlock(world, i + 10, j + 4, k + 2, Blocks.log, 8);
		this.setBlock(world, i + 10, j + 4, k + 18, Blocks.sandstone, 0);
		this.setBlock(world, i + 10, j + 5, k + 0, Blocks.air, 3);
		this.setBlock(world, i + 10, j + 5, k + 1, Blocks.air, 7);
		this.setBlock(world, i + 10, j + 5, k + 2, Blocks.sandstone, 0);
		this.setBlock(world, i + 10, j + 5, k + 4, Blocks.lit_redstone_lamp, 0);
		this.setBlock(world, i + 10, j + 5, k + 7, Blocks.lit_redstone_lamp, 0);
		this.setBlock(world, i + 10, j + 5, k + 10, Blocks.lit_redstone_lamp, 0);
		this.setBlock(world, i + 10, j + 5, k + 13, Blocks.lit_redstone_lamp, 0);
		this.setBlock(world, i + 10, j + 5, k + 16, Blocks.lit_redstone_lamp, 0);
		this.setBlock(world, i + 10, j + 5, k + 18, Blocks.sandstone, 0);
		this.setBlock(world, i + 10, j + 6, k + 1, Blocks.air, 3);
		this.setBlock(world, i + 10, j + 6, k + 2, Blocks.planks, 1);
		this.setBlock(world, i + 10, j + 6, k + 3, Blocks.planks, 1);
		this.setBlock(world, i + 10, j + 6, k + 4, Blocks.lit_redstone_lamp, 0);
		this.setBlock(world, i + 10, j + 6, k + 5, Blocks.planks, 1);
		this.setBlock(world, i + 10, j + 6, k + 6, Blocks.planks, 1);
		this.setBlock(world, i + 10, j + 6, k + 7, Blocks.lit_redstone_lamp, 0);
		this.setBlock(world, i + 10, j + 6, k + 8, Blocks.planks, 1);
		this.setBlock(world, i + 10, j + 6, k + 9, Blocks.planks, 1);
		this.setBlock(world, i + 10, j + 6, k + 10, Blocks.lit_redstone_lamp, 0);
		this.setBlock(world, i + 10, j + 6, k + 11, Blocks.planks, 1);
		this.setBlock(world, i + 10, j + 6, k + 12, Blocks.planks, 1);
		this.setBlock(world, i + 10, j + 6, k + 13, Blocks.lit_redstone_lamp, 0);
		this.setBlock(world, i + 10, j + 6, k + 14, Blocks.planks, 1);
		this.setBlock(world, i + 10, j + 6, k + 15, Blocks.planks, 1);
		this.setBlock(world, i + 10, j + 6, k + 16, Blocks.lit_redstone_lamp, 0);
		this.setBlock(world, i + 10, j + 6, k + 17, Blocks.planks, 1);
		this.setBlock(world, i + 10, j + 6, k + 18, Blocks.planks, 1);
		this.setBlock(world, i + 10, j + 7, k + 2, Blocks.log, 2);
		this.setBlock(world, i + 10, j + 7, k + 17, Blocks.planks, 1);
		this.setBlock(world, i + 10, j + 7, k + 18, Blocks.log, 2);
		this.setBlock(world, i + 10, j + 8, k + 2, Blocks.planks, 1);
		this.setBlock(world, i + 10, j + 8, k + 15, Blocks.planks, 1);
		this.setBlock(world, i + 10, j + 8, k + 16, Blocks.wooden_slab, 9);
		this.setBlock(world, i + 10, j + 8, k + 18, Blocks.planks, 1);
		this.setBlock(world, i + 10, j + 9, k + 2, Blocks.log, 2);
		this.setBlock(world, i + 10, j + 9, k + 3, Blocks.planks, 1);
		this.setBlock(world, i + 10, j + 9, k + 4, Blocks.planks, 1);
		this.setBlock(world, i + 10, j + 9, k + 5, Blocks.planks, 1);
		this.setBlock(world, i + 10, j + 9, k + 6, Blocks.planks, 1);
		this.setBlock(world, i + 10, j + 9, k + 7, Blocks.planks, 1);
		this.setBlock(world, i + 10, j + 9, k + 8, Blocks.planks, 1);
		this.setBlock(world, i + 10, j + 9, k + 9, Blocks.planks, 1);
		this.setBlock(world, i + 10, j + 9, k + 10, Blocks.planks, 1);
		this.setBlock(world, i + 10, j + 9, k + 11, Blocks.planks, 1);
		this.setBlock(world, i + 10, j + 9, k + 12, Blocks.planks, 1);
		this.setBlock(world, i + 10, j + 9, k + 13, Blocks.planks, 1);
		this.setBlock(world, i + 10, j + 9, k + 14, Blocks.planks, 1);
		this.setBlock(world, i + 10, j + 9, k + 15, Blocks.planks, 1);
		this.setBlock(world, i + 10, j + 9, k + 16, Blocks.planks, 1);
		this.setBlock(world, i + 10, j + 9, k + 17, Blocks.planks, 1);
		this.setBlock(world, i + 10, j + 9, k + 18, Blocks.log, 2);
		this.setBlock(world, i + 10, j + 10, k + 2, Blocks.planks, 1);
		this.setBlock(world, i + 10, j + 10, k + 3, Blocks.planks, 1);
		this.setBlock(world, i + 10, j + 10, k + 4, Blocks.planks, 1);
		this.setBlock(world, i + 10, j + 10, k + 5, Blocks.planks, 1);
		this.setBlock(world, i + 10, j + 10, k + 6, Blocks.air, 3);
		this.setBlock(world, i + 10, j + 10, k + 7, Blocks.air, 2);
		this.setBlock(world, i + 10, j + 10, k + 8, Blocks.planks, 1);
		this.setBlock(world, i + 10, j + 10, k + 9, Blocks.air, 3);
		this.setBlock(world, i + 10, j + 10, k + 10, Blocks.air, 2);
		this.setBlock(world, i + 10, j + 10, k + 11, Blocks.planks, 1);
		this.setBlock(world, i + 10, j + 10, k + 12, Blocks.air, 3);
		this.setBlock(world, i + 10, j + 10, k + 13, Blocks.air, 2);
		this.setBlock(world, i + 10, j + 10, k + 14, Blocks.planks, 1);
		this.setBlock(world, i + 10, j + 10, k + 15, Blocks.planks, 1);
		this.setBlock(world, i + 10, j + 10, k + 16, Blocks.planks, 1);
		this.setBlock(world, i + 10, j + 10, k + 17, Blocks.planks, 1);
		this.setBlock(world, i + 10, j + 10, k + 18, Blocks.planks, 1);
		this.setBlock(world, i + 10, j + 11, k + 1, Blocks.air, 3);
		this.setBlock(world, i + 10, j + 11, k + 2, Blocks.air, 3);
		this.setBlock(world, i + 10, j + 11, k + 3, Blocks.air, 3);
		this.setBlock(world, i + 10, j + 11, k + 4, Blocks.air, 3);
		this.setBlock(world, i + 10, j + 11, k + 5, Blocks.air, 3);
		this.setBlock(world, i + 10, j + 11, k + 6, Blocks.air, 7);
		this.setBlock(world, i + 10, j + 11, k + 7, Blocks.air, 6);
		this.setBlock(world, i + 10, j + 11, k + 8, Blocks.air, 3);
		this.setBlock(world, i + 10, j + 11, k + 9, Blocks.air, 7);
		this.setBlock(world, i + 10, j + 11, k + 10, Blocks.air, 6);
		this.setBlock(world, i + 10, j + 11, k + 11, Blocks.air, 3);
		this.setBlock(world, i + 10, j + 11, k + 12, Blocks.air, 7);
		this.setBlock(world, i + 10, j + 11, k + 13, Blocks.air, 6);
		this.setBlock(world, i + 10, j + 11, k + 14, Blocks.air, 3);
		this.setBlock(world, i + 10, j + 11, k + 15, Blocks.air, 3);
		this.setBlock(world, i + 10, j + 11, k + 16, Blocks.air, 3);
		this.setBlock(world, i + 10, j + 11, k + 17, Blocks.air, 3);
		this.setBlock(world, i + 10, j + 11, k + 18, Blocks.air, 3);
		this.setBlock(world, i + 10, j + 11, k + 19, Blocks.air, 3);
		this.setBlock(world, i + 10, j + 12, k + 1, Blocks.air, 3);
		this.setBlock(world, i + 10, j + 12, k + 2, Blocks.air, 3);
		this.setBlock(world, i + 10, j + 12, k + 3, Blocks.air, 3);
		this.setBlock(world, i + 10, j + 12, k + 4, Blocks.air, 3);
		this.setBlock(world, i + 10, j + 12, k + 5, Blocks.air, 3);
		this.setBlock(world, i + 10, j + 12, k + 6, Blocks.air, 3);
		this.setBlock(world, i + 10, j + 12, k + 7, Blocks.air, 3);
		this.setBlock(world, i + 10, j + 12, k + 8, Blocks.air, 3);
		this.setBlock(world, i + 10, j + 12, k + 9, Blocks.air, 3);
		this.setBlock(world, i + 10, j + 12, k + 10, Blocks.air, 3);
		this.setBlock(world, i + 10, j + 12, k + 11, Blocks.air, 3);
		this.setBlock(world, i + 10, j + 12, k + 12, Blocks.air, 3);
		this.setBlock(world, i + 10, j + 12, k + 13, Blocks.air, 3);
		this.setBlock(world, i + 10, j + 12, k + 14, Blocks.air, 3);
		this.setBlock(world, i + 10, j + 12, k + 15, Blocks.air, 3);
		this.setBlock(world, i + 10, j + 12, k + 16, Blocks.air, 3);
		this.setBlock(world, i + 10, j + 12, k + 17, Blocks.air, 3);
		this.setBlock(world, i + 10, j + 12, k + 18, Blocks.air, 3);
		this.setBlock(world, i + 10, j + 12, k + 19, Blocks.air, 3);
		this.setBlock(world, i + 11, j + 0, k + 2, Blocks.cobblestone, 0);
		this.setBlock(world, i + 11, j + 0, k + 3, Blocks.cobblestone, 0);
		this.setBlock(world, i + 11, j + 0, k + 4, Blocks.cobblestone, 0);
		this.setBlock(world, i + 11, j + 0, k + 5, Blocks.cobblestone, 0);
		this.setBlock(world, i + 11, j + 0, k + 6, Blocks.cobblestone, 0);
		this.setBlock(world, i + 11, j + 0, k + 7, Blocks.cobblestone, 0);
		this.setBlock(world, i + 11, j + 0, k + 8, Blocks.cobblestone, 0);
		this.setBlock(world, i + 11, j + 0, k + 9, Blocks.cobblestone, 0);
		this.setBlock(world, i + 11, j + 0, k + 10, Blocks.cobblestone, 0);
		this.setBlock(world, i + 11, j + 0, k + 11, Blocks.cobblestone, 0);
		this.setBlock(world, i + 11, j + 0, k + 12, Blocks.cobblestone, 0);
		this.setBlock(world, i + 11, j + 0, k + 13, Blocks.cobblestone, 0);
		this.setBlock(world, i + 11, j + 0, k + 14, Blocks.cobblestone, 0);
		this.setBlock(world, i + 11, j + 0, k + 15, Blocks.cobblestone, 0);
		this.setBlock(world, i + 11, j + 0, k + 16, Blocks.cobblestone, 0);
		this.setBlock(world, i + 11, j + 0, k + 17, Blocks.cobblestone, 0);
		this.setBlock(world, i + 11, j + 0, k + 18, Blocks.cobblestone, 0);
		this.setBlock(world, i + 11, j + 0, k + 19, Blocks.planks, 0);
		this.setBlock(world, i + 11, j + 0, k + 20, Blocks.planks, 0);
		this.setBlock(world, i + 11, j + 0, k + 21, Blocks.planks, 0);
		this.setBlock(world, i + 11, j + 0, k + 22, Blocks.planks, 0);
		this.setBlock(world, i + 11, j + 0, k + 23, Blocks.planks, 0);
		this.setBlock(world, i + 11, j + 0, k + 24, Blocks.planks, 0);
		this.setBlock(world, i + 11, j + 0, k + 25, Blocks.planks, 0);
		this.setBlock(world, i + 11, j + 1, k + 2, Blocks.sandstone, 0);
		this.setBlock(world, i + 11, j + 1, k + 3, Blocks.stone_slab, 3);
		this.setBlock(world, i + 11, j + 1, k + 4, Blocks.stone_slab, 3);
		this.setBlock(world, i + 11, j + 1, k + 5, Blocks.stone_slab, 3);
		this.setBlock(world, i + 11, j + 1, k + 6, Blocks.stone_slab, 3);
		this.setBlock(world, i + 11, j + 1, k + 7, Blocks.stone_slab, 3);
		this.setBlock(world, i + 11, j + 1, k + 8, Blocks.stone_slab, 3);
		this.setBlock(world, i + 11, j + 1, k + 9, Blocks.stone_slab, 3);
		this.setBlock(world, i + 11, j + 1, k + 10, Blocks.stone_slab, 3);
		this.setBlock(world, i + 11, j + 1, k + 11, Blocks.stone_slab, 3);
		this.setBlock(world, i + 11, j + 1, k + 12, Blocks.stone_slab, 3);
		this.setBlock(world, i + 11, j + 1, k + 13, Blocks.stone_slab, 3);
		this.setBlock(world, i + 11, j + 1, k + 14, Blocks.stone_slab, 3);
		this.setBlock(world, i + 11, j + 1, k + 15, Blocks.stone_slab, 3);
		this.setBlock(world, i + 11, j + 1, k + 16, Blocks.stone_slab, 3);
		this.setBlock(world, i + 11, j + 1, k + 17, Blocks.stone_slab, 3);
		this.setBlock(world, i + 11, j + 1, k + 18, Blocks.sandstone, 0);
		this.setBlock(world, i + 11, j + 1, k + 21, Blocks.spruce_stairs, 4);
		this.setBlock(world, i + 11, j + 1, k + 22, Blocks.spruce_stairs, 7);
		this.setBlock(world, i + 11, j + 1, k + 25, Blocks.fence, 0);
		this.setBlock(world, i + 11, j + 2, k + 2, Blocks.planks, 1);
		this.setBlock(world, i + 11, j + 2, k + 18, Blocks.air, 12);
		this.setBlock(world, i + 11, j + 3, k + 2, Blocks.planks, 1);
		this.setBlock(world, i + 11, j + 3, k + 18, Blocks.air, 12);
		this.setBlock(world, i + 11, j + 4, k + 2, Blocks.sandstone, 0);
		this.setBlock(world, i + 11, j + 4, k + 18, Blocks.sandstone, 0);
		this.setBlock(world, i + 11, j + 5, k + 0, Blocks.air, 3);
		this.setBlock(world, i + 11, j + 5, k + 1, Blocks.air, 7);
		this.setBlock(world, i + 11, j + 5, k + 2, Blocks.sandstone, 0);
		this.setBlock(world, i + 11, j + 5, k + 18, Blocks.sandstone, 0);
		this.setBlock(world, i + 11, j + 6, k + 1, Blocks.air, 3);
		this.setBlock(world, i + 11, j + 6, k + 2, Blocks.planks, 5);
		this.setBlock(world, i + 11, j + 6, k + 3, Blocks.planks, 1);
		this.setBlock(world, i + 11, j + 6, k + 4, Blocks.planks, 1);
		this.setBlock(world, i + 11, j + 6, k + 5, Blocks.planks, 1);
		this.setBlock(world, i + 11, j + 6, k + 6, Blocks.planks, 1);
		this.setBlock(world, i + 11, j + 6, k + 7, Blocks.planks, 1);
		this.setBlock(world, i + 11, j + 6, k + 8, Blocks.planks, 1);
		this.setBlock(world, i + 11, j + 6, k + 9, Blocks.planks, 1);
		this.setBlock(world, i + 11, j + 6, k + 10, Blocks.planks, 1);
		this.setBlock(world, i + 11, j + 6, k + 11, Blocks.planks, 1);
		this.setBlock(world, i + 11, j + 6, k + 12, Blocks.planks, 1);
		this.setBlock(world, i + 11, j + 6, k + 13, Blocks.planks, 1);
		this.setBlock(world, i + 11, j + 6, k + 14, Blocks.planks, 1);
		this.setBlock(world, i + 11, j + 6, k + 15, Blocks.planks, 1);
		this.setBlock(world, i + 11, j + 6, k + 16, Blocks.planks, 1);
		this.setBlock(world, i + 11, j + 6, k + 17, Blocks.planks, 1);
		this.setBlock(world, i + 11, j + 6, k + 18, Blocks.planks, 5);
		this.setBlock(world, i + 11, j + 7, k + 2, Blocks.planks, 1);
		this.setBlock(world, i + 11, j + 7, k + 3, Blocks.planks, 1);
		this.setBlock(world, i + 11, j + 7, k + 4, Blocks.planks, 1);
		this.setBlock(world, i + 11, j + 7, k + 5, Blocks.planks, 1);
		this.setBlock(world, i + 11, j + 7, k + 6, Blocks.planks, 1);
		this.setBlock(world, i + 11, j + 7, k + 7, Blocks.planks, 1);
		this.setBlock(world, i + 11, j + 7, k + 8, Blocks.planks, 1);
		this.setBlock(world, i + 11, j + 7, k + 9, Blocks.planks, 1);
		this.setBlock(world, i + 11, j + 7, k + 10, Blocks.planks, 1);
		this.setBlock(world, i + 11, j + 7, k + 11, Blocks.planks, 1);
		this.setBlock(world, i + 11, j + 7, k + 12, Blocks.planks, 1);
		this.setBlock(world, i + 11, j + 7, k + 13, Blocks.planks, 1);
		this.setBlock(world, i + 11, j + 7, k + 14, Blocks.planks, 1);
		this.setBlock(world, i + 11, j + 7, k + 15, Blocks.planks, 1);
		this.setBlock(world, i + 11, j + 7, k + 16, Blocks.planks, 1);
		this.setBlock(world, i + 11, j + 7, k + 17, Blocks.planks, 1);
		this.setBlock(world, i + 11, j + 7, k + 18, Blocks.planks, 1);
		this.setBlock(world, i + 11, j + 8, k + 2, Blocks.planks, 5);
		this.setBlock(world, i + 11, j + 8, k + 3, Blocks.planks, 1);
		this.setBlock(world, i + 11, j + 8, k + 4, Blocks.planks, 1);
		this.setBlock(world, i + 11, j + 8, k + 5, Blocks.planks, 1);
		this.setBlock(world, i + 11, j + 8, k + 6, Blocks.planks, 1);
		this.setBlock(world, i + 11, j + 8, k + 7, Blocks.planks, 1);
		this.setBlock(world, i + 11, j + 8, k + 8, Blocks.planks, 1);
		this.setBlock(world, i + 11, j + 8, k + 9, Blocks.planks, 1);
		this.setBlock(world, i + 11, j + 8, k + 10, Blocks.planks, 1);
		this.setBlock(world, i + 11, j + 8, k + 11, Blocks.planks, 1);
		this.setBlock(world, i + 11, j + 8, k + 12, Blocks.planks, 1);
		this.setBlock(world, i + 11, j + 8, k + 13, Blocks.planks, 1);
		this.setBlock(world, i + 11, j + 8, k + 14, Blocks.planks, 1);
		this.setBlock(world, i + 11, j + 8, k + 15, Blocks.planks, 1);
		this.setBlock(world, i + 11, j + 8, k + 16, Blocks.planks, 1);
		this.setBlock(world, i + 11, j + 8, k + 17, Blocks.planks, 1);
		this.setBlock(world, i + 11, j + 8, k + 18, Blocks.planks, 5);
		this.setBlock(world, i + 11, j + 9, k + 1, Blocks.air, 3);
		this.setBlock(world, i + 11, j + 9, k + 2, Blocks.air, 3);
		this.setBlock(world, i + 11, j + 9, k + 3, Blocks.air, 3);
		this.setBlock(world, i + 11, j + 9, k + 4, Blocks.air, 3);
		this.setBlock(world, i + 11, j + 9, k + 5, Blocks.air, 3);

		generate2(world, rand, i, j, k);
		return true;
	}

	public boolean generate2(World world, Random rand, int i, int j, int k) {
		this.setBlock(world, i + 11, j + 9, k + 6, Blocks.air, 3);
		this.setBlock(world, i + 11, j + 9, k + 7, Blocks.air, 3);
		this.setBlock(world, i + 11, j + 9, k + 8, Blocks.air, 3);
		this.setBlock(world, i + 11, j + 9, k + 9, Blocks.air, 3);
		this.setBlock(world, i + 11, j + 9, k + 10, Blocks.air, 3);
		this.setBlock(world, i + 11, j + 9, k + 11, Blocks.air, 3);
		this.setBlock(world, i + 11, j + 9, k + 12, Blocks.air, 3);
		this.setBlock(world, i + 11, j + 9, k + 13, Blocks.air, 3);
		this.setBlock(world, i + 11, j + 9, k + 14, Blocks.air, 3);
		this.setBlock(world, i + 11, j + 9, k + 15, Blocks.air, 3);
		this.setBlock(world, i + 11, j + 9, k + 16, Blocks.air, 3);
